Workbook
Name DEPT: #REF!
Name DEPT: #REF!
Name DEPT: #REF!
Name DEPT: #REF!
Name DEPT: #REF!
Name DEPT: #REF!
Name DEPT: #REF!
Name DEPT: #REF!
Name DEPT: #REF!
Name DEPT: #REF!
Name trial: #REF!
Name trial: #REF!
Name trial: #REF!
Name trial: #REF!
Name trial: #REF!
Name trial: #REF!
Name trial: #REF!
Name trial: #REF!
Name trial: #REF!
Name trial: #REF!
Name trial: #REF!
Name trial: #REF!
Name trial: #REF!
Name trial: #REF!
Name TRIALBAL: #REF!
Name TRIALBAL: #REF!
Name TRIALBAL: #REF!
Name TRIALBAL: #REF!
Name TRIALBAL: #REF!
Name TRIALBAL: #REF!
Name TRIALBAL: #REF!
Name TRIALBAL: #REF!
Name TRIALBAL: #REF!
Name TRIALBAL: #REF!
Name TRIALBAL: #REF!
Name TRIALBAL: #REF!
Name TRIALBAL: #REF!
Name TRIALBAL: #REF!
Name TRIALBAL: #REF!

Sheet Cover Page
A1: Financial Reports F01 - F39
A2: Company Accounts
A3: S/No | B3: Old | C3: New | D3: Report Name | F3: Format | H3: User/Comment
A4: 1 | B4: F101 | C4: F21 | D4: P&L Account against Budget | E4: Normal | F4: A4 P | G4: 000s | H4: P&L against budget for Coy, Div, Dept, Sec & Units
A5: =A4+1 -> 2 | B5: F101S | C5: F21S | D5: P&L Account against Budget | E5: Normal | F5: A4 P | G5: 000s | H5: Convert to S$
A6: =A5+1 -> 3 | C6: F21R | D6: P&L Account against Budget (Raw) | E6: Normal | F6: A4 P | G6: Actual | H6: In Actual Data for easy checking of entries.
A7: =A6+1 -> 4 | B7: F102 | C7: F22 | D7: P&L Account by Month | E7: Brief | F7: A4 L | G7: 000s | H7: P&L Statement Actual by Month for Coy, Div, Dept, Sec & Units
A8: =A7+1 -> 5 | B8: F102S | C8: F22S | D8: P&L Account by Month | E8: Brief | F8: A4 L | G8: 000s | H8: Convert to S$
A9: =A8+1 -> 6 | B9: F103 | C9: F23 | D9: P&L Account by Div/Dept/Sec/Units | E9: Normal (9) | F9: A4 P | G9: 000s | H9: P&L Statement Actual for all Div/Dept/Sec/Units
A10: =A9+1 -> 7 | B10: F121 | C10: F24 | D10: Manufacturing Account against Budget | E10: Normal (9) | F10: A4 P | G10: 000s | H10: Manufacturing Account against budget for Coy, Div, Dept, Sec & Units
A11: =A10+1 -> 8 | B11: F122 | C11: F25 | D11: Manufacturing Account by Div/Dept/Sec/Units | E11: Normal (9) | F11: A4 P | G11: 000s | H11: Manufacturing Account for all Div/Dept/Sec/Units
A12: =A11+1 -> 9 | C12: F26M | D12: ASU Manufacturing Account by Products by Month | F12: A4 P | G12: 000s
A13: =A12+1 -> 10 | C13: F26Y | D13: ASU Manufacturing Account by Products Year To Date | F13: A4 P | G13: 000s
A14: =A13+1 -> 11 | B14: F131 | C14: F30 | D14: Balance Sheet | F14: A4 P | G14: 000s
A15: =A14+1 -> 12 | C15: F30R | D15: Balance Sheet (Raw) | F15: A4 P | G15: Actual | H15: In Actual Data for easy checking of entries.
A16: =A15+1 -> 13 | B16: F141 | C16: F31 | D16: Detailed P&L Account | F16: A4 L | G16: 000s
A17: =A16+1 -> 14 | B17: F142 | C17: F32 | D17: Detailed Manufacturing Account | F17: A4 L | G17: 000s
A18: =A17+1 -> 15 | B18: F151 | C18: F33 | D18: Detailed Balance Sheet | F18: A4 P | G18: 000s
A19: =A18+1 -> 16 | B19: New | C19: F38 | D19: TNSC Reporting Package
A20: =A19+1 -> 17 | B20: New | C20: F39 | D20: SAF Report

Sheet F21
A1: LEEDEN NATIONAL OXYGEN LTD | D1: AS OF: 11-Oct-2017 | H1: FOR THE MONTH OF: Sep -17
A2: DIVISION: | D2: DEPT: | H2: SECTION:
A3: F21 PROFIT & LOSS ACCOUNT | D3: CURRENCY: 000s | H3: FX: 0.00
D4: CURRENT MONTH | H4: YEAR TO DATE
D5: Aug-17 | E5: Sep-17 | F5: Budget | G5: Variance | H5: Actual | I5: Budget | J5: Variance | K5: Last Year | L5: Variance
A6: 1 | B6: External Sales | C6: 5001 to 5029, 5051 to 5099
A7: =A6+1 -> 2 | B7: Interco Sales | C7: 5031 to 5049
A8: =A7+1 -> 3 | B8: Total Sales | C8: =SUM(C6:C7)
A9: =A8+1 -> 4 | B9: Cost of External Sales | C9: 5101 to 5119, 5141 to 5499, 6000 to 6999
A10: =A9+1 -> 5 | B10: Cost of Interco Sales | C10: 5121 to 5139
A11: =A10+1 -> 6 | B11: Total Cost of Sales | C11: =SUM(C9:C10)
A12: =A11+1 -> 7 | B12: Gross Profit | C12: =C8+C11
A13: =A12+1 -> 8 | B13: Commission/Mgt Income | C13: 5501 to 5509
A14: =A13+1 -> 9 | B14: Gain/(Loss) Disposal of FA | C14: 9101
A15: =A14+1 -> 10 | B15: Other Op Income | C15: 5511 to 5599, 9001 to 9019, 9041Credit, 9102 to 9109Credit
A16: =A15+1 -> 11 | B16: Other Op Expense | C16: 5601 to 5999, 9041Debit, 9102 to 9109Debit, 9111 to 9115, 9117 to 9199
A17: =A16+1 -> 12 | B17: Total Oth Op Income/ (Exp) | C17: =SUM(C13:C16)
A18: =A17+1 -> 13 | B18: Personnel Related Cost | C18: 7000 to 7099
... A60: =A59+1 -> 55 | B60: Dividend Declared | C60: 4902
B61: Performance Indicators | D61: Aug-17 | E61: Sep-17 | F61: Budget | G61: Variance | H61: Actual | I61: Budget | J61: Variance | K61: Last Year | L61: Variance
A62: =A61+1 -> 1 | B62: Gross Profits Margin % | C62: Gross Profits/Total Sales
A63: =A62+1 -> 2 | B63: - External Sales GP % | C63: (External Sales - Cost of External Sales)/External Sales
A64: 3 | B64: - Interco Sales GP % | C64: (Interco Sales - Cost of Interco Sales)/Interco Sales
A65: 4 | B65: Selling & Dist Margin % | C65: -Total S&D Exps/Total Sales
A66: 5 | B66: A&G Margin Direct % | C66: -Total Direct A&G Exps/Total Sales
A67: 6 | B67: A&G Margin Total % | C67: -Total A&G Exps/Total Sales
A68: 7 | B68: Operating Profit Margin % | C68: Profits from Operations/Total Sales
A69: 8 | B69: Profits Before Taxation % | C69: Profits Before Taxation/Total Sales
A70: 9 | B70: Profit After Taxation % | C70: Profits after Taxation/Total Sales

Sheet F21S
A1: LEEDEN NATIONAL OXYGEN LTD | D1: ='F21'!D1:G1 -> AS OF: 11-Oct-2017 | H1: ='F21'!H1:L1 -> FOR THE MONTH OF: Sep -17
A2: DIVISION: COMPANY | D2: DEPT: | H2: SECTION:
A3: F21S PROFIT & LOSS ACCOUNT | D3: CURRENCY: SGD 000s | H3: FX: 0.00
D4: CURRENT MONTH | H4: YEAR TO DATE
D5: Aug-17 | E5: Sep-17 | F5: Budget | G5: Variance | H5: Actual | I5: Budget | J5: Variance | K5: Last Year | L5: Variance
A6: 1 | B6: ='F21'!B6 -> External Sales | C6: ='F21'!C6 -> 5001 to 5029, 5051 to 5099
A7: =A6+1 -> 2 | B7: ='F21'!B7 -> Interco Sales | C7: ='F21'!C7 -> 5031 to 5049
A8: =A7+1 -> 3 | B8: ='F21'!B8 -> Total Sales | C8: ='F21'!C8 -> =SUM(C6:C7)
A9: =A8+1 -> 4 | B9: ='F21'!B9 -> Cost of External Sales | C9: ='F21'!C9 -> 5101 to 5119, 5141 to 5499, 6000 to 6999
A10: =A9+1 -> 5 | B10: ='F21'!B10 -> Cost of Interco Sales | C10: ='F21'!C10 -> 5121 to 5139
A11: =A10+1 -> 6 | B11: ='F21'!B11 -> Total Cost of Sales | C11: ='F21'!C11 -> =SUM(C9:C10)
A12: =A11+1 -> 7 | B12: ='F21'!B12 -> Gross Profit | C12: ='F21'!C12 -> =C8+C11
A13: =A12+1 -> 8 | B13: ='F21'!B13 -> Commission/Mgt Income | C13: ='F21'!C13 -> 5501 to 5509
A14: =A13+1 -> 9 | B14: ='F21'!B14 -> Gain/(Loss) Disposal of FA | C14: ='F21'!C14 -> 9101
A15: =A14+1 -> 10 | B15: ='F21'!B15 -> Other Op Income | C15: ='F21'!C15 -> 5511 to 5599, 9001 to 9019, 9041Credit, 9102 to 9109Credit
A16: =A15+1 -> 11 | B16: ='F21'!B16 -> Other Op Expense | C16: ='F21'!C16 -> 5601 to 5999, 9041Debit, 9102 to 9109Debit, 9111 to 9115, 9117 to 9199
A17: =A16+1 -> 12 | B17: ='F21'!B17 -> Total Oth Op Income/ (Exp) | C17: ='F21'!C17 -> =SUM(C13:C16)
A18: =A17+1 -> 13 | B18: ='F21'!B18 -> Personnel Related Cost | C18: ='F21'!C18 -> 7000 to 7099
... A60: =A59+1 -> 55 | B60: ='F21'!B60 -> Dividend Declared | C60: ='F21'!C60 -> 4902
B61: ='F21'!B61 -> Performance Indicators | D61: Aug-17 | E61: Sep-17 | F61: Budget | G61: Variance | H61: Actual | I61: Budget | J61: Variance | K61: Last Year | L61: Variance
A62: =A61+1 -> 1 | B62: ='F21'!B62 -> Gross Profits Margin % | C62: ='F21'!C62 -> Gross Profits/Total Sales
A63: =A62+1 -> 2 | B63: ='F21'!B63 -> - External Sales GP % | C63: ='F21'!C63 -> (External Sales - Cost of External Sales)/External Sales
A64: 3 | B64: ='F21'!B64 -> - Interco Sales GP % | C64: ='F21'!C64 -> (Interco Sales - Cost of Interco Sales)/Interco Sales
A65: 4 | B65: ='F21'!B65 -> Selling & Dist Margin % | C65: ='F21'!C65 -> -Total S&D Exps/Total Sales
A66: 5 | B66: ='F21'!B66 -> A&G Margin Direct % | C66: ='F21'!C66 -> -Total Direct A&G Exps/Total Sales
A67: 6 | B67: ='F21'!B67 -> A&G Margin Total % | C67: ='F21'!C67 -> -Total A&G Exps/Total Sales
A68: 7 | B68: ='F21'!B68 -> Operating Profit Margin % | C68: ='F21'!C68 -> Profits from Operations/Total Sales
A69: 8 | B69: ='F21'!B69 -> Profits Before Taxation % | C69: ='F21'!C69 -> Profits Before Taxation/Total Sales
A70: 9 | B70: ='F21'!B70 -> Profit After Taxation % | C70: ='F21'!C70 -> Profits after Taxation/Total Sales

Sheet F21R
A1: LEEDEN NATIONAL OXYGEN LTD | D1: =F21S!D1 -> AS OF: 11-Oct-2017 | H1: =F21S!H1 -> FOR THE MONTH OF: Sep -17
A2: DIVISION: COMPANY | D2: DEPT: | H2: SECTION:
A3: F21R PROFIT & LOSS ACCOUNT (RAW) | D3: CURRENCY: | H3: FX: 0.00
D4: CURRENT MONTH | H4: YEAR TO DATE
D5: Aug-17 | E5: Sep-17 | F5: Budget | G5: Variance | H5: Actual | I5: Budget | J5: Variance | K5: Last Year | L5: Variance
A6: 1 | B6: =F21S!B6 -> External Sales | C6: =F21S!C6 -> 5001 to 5029, 5051 to 5099
A7: =A6+1 -> 2 | B7: =F21S!B7 -> Interco Sales | C7: =F21S!C7 -> 5031 to 5049
A8: =A7+1 -> 3 | B8: =F21S!B8 -> Total Sales | C8: =F21S!C8 -> =SUM(C6:C7)
A9: =A8+1 -> 4 | B9: =F21S!B9 -> Cost of External Sales | C9: =F21S!C9 -> 5101 to 5119, 5141 to 5499, 6000 to 6999
A10: =A9+1 -> 5 | B10: =F21S!B10 -> Cost of Interco Sales | C10: =F21S!C10 -> 5121 to 5139
A11: =A10+1 -> 6 | B11: =F21S!B11 -> Total Cost of Sales | C11: =F21S!C11 -> =SUM(C9:C10)
A12: =A11+1 -> 7 | B12: =F21S!B12 -> Gross Profit | C12: =F21S!C12 -> =C8+C11
A13: =A12+1 -> 8 | B13: =F21S!B13 -> Commission/Mgt Income | C13: =F21S!C13 -> 5501 to 5509
A14: =A13+1 -> 9 | B14: =F21S!B14 -> Gain/(Loss) Disposal of FA | C14: =F21S!C14 -> 9101
A15: =A14+1 -> 10 | B15: =F21S!B15 -> Other Op Income | C15: =F21S!C15 -> 5511 to 5599, 9001 to 9019, 9041Credit, 9102 to 9109Credit
A16: =A15+1 -> 11 | B16: =F21S!B16 -> Other Op Expense | C16: =F21S!C16 -> 5601 to 5999, 9041Debit, 9102 to 9109Debit, 9111 to 9115, 9117 to 9199
A17: =A16+1 -> 12 | B17: =F21S!B17 -> Total Oth Op Income/ (Exp) | C17: =F21S!C17 -> =SUM(C13:C16)
A18: =A17+1 -> 13 | B18: =F21S!B18 -> Personnel Related Cost | C18: =F21S!C18 -> 7000 to 7099
... A60: =A59+1 -> 55 | B60: =F21S!B60 -> Dividend Declared | C60: =F21S!C60 -> 4902
B61: =F21S!B61 -> Performance Indicators | D61: Aug-17 | E61: Sep-17 | F61: Budget | G61: Variance | H61: Actual | I61: Budget | J61: Variance | K61: Last Year | L61: Variance
A62: =A61+1 -> 1 | B62: =F21S!B62 -> Gross Profits Margin % | C62: =F21S!C62 -> Gross Profits/Total Sales
A63: =A62+1 -> 2 | B63: =F21S!B63 -> - External Sales GP % | C63: =F21S!C63 -> (External Sales - Cost of External Sales)/External Sales
A64: 3 | B64: =F21S!B64 -> - Interco Sales GP % | C64: =F21S!C64 -> (Interco Sales - Cost of Interco Sales)/Interco Sales
A65: 4 | B65: =F21S!B65 -> Selling & Dist Margin % | C65: =F21S!C65 -> -Total S&D Exps/Total Sales
A66: 5 | B66: =F21S!B66 -> A&G Margin Direct % | C66: =F21S!C66 -> -Total Direct A&G Exps/Total Sales
A67: 6 | B67: =F21S!B67 -> A&G Margin Total % | C67: =F21S!C67 -> -Total A&G Exps/Total Sales
A68: 7 | B68: =F21S!B68 -> Operating Profit Margin % | C68: =F21S!C68 -> Profits from Operations/Total Sales
A69: 8 | B69: =F21S!B69 -> Profits Before Taxation % | C69: =F21S!C69 -> Profits Before Taxation/Total Sales
A70: 9 | B70: =F21S!B70 -> Profit After Taxation % | C70: =F21S!C70 -> Profits after Taxation/Total Sales

Sheet F22
A1: LEEDEN NATIONAL OXYGEN LTD | D1: =F21S!D1 -> AS OF: 11-Oct-2017 | O1: FOR THE YEAR OF: 2018
A2: DIVISION: | D2: DEPT: | O2: SECTION:
A3: F22 P&L ACCOUNT BY MONTH | D3: CURRENCY: 000s | O3: FX: 0.00
D4: 42826 | E4: 42856 | F4: 42887 | G4: 42917 | H4: 42948 | I4: 42979 | J4: 43009 | K4: 43040 | L4: 43070 | M4: 43101 | N4: 43132 | O4: 43160 | P4: Total | Q4: FY 2017 | R4: Variance %
A5: 1 | B5: =F21R!B6 -> External Sales | C5: =F21R!C6 -> 5001 to 5029, 5051 to 5099
A6: =A5+1 -> 2 | B6: =F21R!B7 -> Interco Sales | C6: =F21R!C7 -> 5031 to 5049
A7: =A6+1 -> 3 | B7: =F21R!B8 -> Total Sales | C7: =SUM(C5:C6)
A8: =A7+1 -> 4 | B8: =F21R!B9 -> Cost of External Sales | C8: =F21R!C9 -> 5101 to 5119, 5141 to 5499, 6000 to 6999
A9: =A8+1 -> 5 | B9: =F21R!B10 -> Cost of Interco Sales | C9: =F21R!C10 -> 5121 to 5139
A10: =A9+1 -> 6 | B10: =F21R!B11 -> Total Cost of Sales | C10: =SUM(C8:C9)
A11: =A10+1 -> 7 | B11: =F21R!B12 -> Gross Profit | C11: =C7+C10
A12: =A11+1 -> 8 | B12: =F21R!B13 -> Commission/Mgt Income | C12: =F21R!C13 -> 5501 to 5509
A13: =A12+1 -> 9 | B13: =F21R!B14 -> Gain/(Loss) Disposal of FA | C13: =F21R!C14 -> 9101
A14: =A13+1 -> 10 | B14: =F21R!B15 -> Other Op Income | C14: =F21R!C15 -> 5511 to 5599, 9001 to 9019, 9041Credit, 9102 to 9109Credit
A15: =A14+1 -> 11 | B15: =F21R!B16 -> Other Op Expense | C15: =F21R!C16 -> 5601 to 5999, 9041Debit, 9102 to 9109Debit, 9111 to 9115, 9117 to 9199
A16: =A15+1 -> 12 | B16: =F21R!B17 -> Total Oth Op Income/ (Exp) | C16: =SUM(C12:C15)
A17: =A16+1 -> 13 | B17: Selling & Distribution | C17: 7000 to 7999
A18: =A17+1 -> 14 | B18: A&G Direct Expenses | C18: 8000 to 8699
A19: =A18+1 -> 15 | B19: A&G Other Expenses | C19: 8700 to 8799
A20: =A19+1 -> 16 | B20: =F21R!B49 -> Profit from Operations | C20: =C11+C16+SUM(C17:C19)
A21: =A20+1 -> 17 | B21: =F21R!B50 -> Interest Income | C21: =F21R!C50 -> 9023
A22: =A21+1 -> 18 | B22: =F21R!B51 -> Interest (Expense) | C22: =F21R!C51 -> 8801 to 8809
A23: =A22+1 -> 19 | B23: =F21R!B52 -> Derivatives Gain/(Loss) | C23: =F21R!C52 -> 8821 to 8822
A24: =A23+1 -> 20 | B24: =F21R!B53 -> Forex Gain/(Loss) | C24: =F21R!C53 -> 8831 to 8832
A25: =A24+1 -> 21 | B25: =F21R!B54 -> Dividend Income | C25: =F21R!C54 -> 9021
A26: =A25+1 -> 22 | B26: =F21R!B55 -> Other Non-Op Income/(Exp) | C26: =F21R!C55 -> 9031, 9116, 9200 to 9211
A27: =A26+1 -> 23 | B27: =F21R!B56 -> Total Non-Op Income/(Exp) | C27: =F21R!C56 -> =SUM(C50:C55)
A28: =A27+1 -> 24 | B28: =F21R!B57 -> Profit Before Taxation | C28: =F21R!C57 -> =C49+C56
A29: =A28+1 -> 25 | B29: =F21R!B58 -> Less: Taxation | C29: =F21R!C58 -> 9400 to 9999
A30: =A29+1 -> 26 | B30: =F21R!B59 -> Profits After Taxation | C30: =F21R!C59 -> =C57+C58
A31: =A30+1 -> 27 | B31: =F21R!B60 -> Dividend Declared | C31: =F21R!C60 -> 4902
B32: Performance Indicators | D32: 42826 | E32: 42856 | F32: 42887 | G32: 42917 | H32: 42948 | I32: 42979 | J32: 43009 | K32: 43040 | L32: 43070 | M32: 43101 | N32: 43132 | O32: 43160 | P32: Total | Q32: FY 2017 | R32: Variance %
A33: =A32+1 -> 1 | B33: Gross Profits Margin % | C33: =F21R!C62 -> Gross Profits/Total Sales
A34: =A33+1 -> 2 | B34: - External Sales GP % | C34: =F21R!C63 -> (External Sales - Cost of External Sales)/External Sales
A35: =A34+1 -> 3 | B35: - Interco Sales GP % | C35: =F21R!C64 -> (Interco Sales - Cost of Interco Sales)/Interco Sales
A36: =A35+1 -> 4 | B36: Selling & Dist Margin % | C36: =F21R!C65 -> -Total S&D Exps/Total Sales
A37: =A36+1 -> 5 | B37: A&G Margin Direct % | C37: =F21R!C66 -> -Total Direct A&G Exps/Total Sales
A38: =A37+1 -> 6 | B38: A&G Margin Total % | C38: =F21R!C67 -> -Total A&G Exps/Total Sales
A39: =A38+1 -> 7 | B39: Operating Profits Margin % | C39: =F21R!C68 -> Profits from Operations/Total Sales
A40: =A39+1 -> 8 | B40: Profits Before Taxation % | C40: =F21R!C69 -> Profits Before Taxation/Total Sales
...

Sheet F22S
A1: LEEDEN NATIONAL OXYGEN LTD | D1: ='F22'!D1:N1 -> AS OF: 11-Oct-2017 | O1: ='F22'!O1 -> FOR THE YEAR OF: 2018
A2: DIVISION: HO CORPORATE | D2: DEPT: ADMIN | O2: SECTION:
A3: F22S P&L ACCOUNT BY MONTH | D3: CURRENCY: SGD 000s | O3: FX: 0.00
D4: 42826 | E4: 42856 | F4: 42887 | G4: 42917 | H4: 42948 | I4: 42979 | J4: 43009 | K4: 43040 | L4: 43070 | M4: 43101 | N4: 43132 | O4: 43160 | P4: Total | Q4: FY 2017 | R4: Variance %
A5: 1 | B5: ='F22'!B5 -> External Sales | C5: ='F22'!C5 -> 5001 to 5029, 5051 to 5099
A6: =A5+1 -> 2 | B6: ='F22'!B6 -> Interco Sales | C6: ='F22'!C6 -> 5031 to 5049
A7: =A6+1 -> 3 | B7: ='F22'!B7 -> Total Sales | C7: ='F22'!C7 -> =SUM(C5:C6)
A8: =A7+1 -> 4 | B8: ='F22'!B8 -> Cost of External Sales | C8: ='F22'!C8 -> 5101 to 5119, 5141 to 5499, 6000 to 6999
A9: =A8+1 -> 5 | B9: ='F22'!B9 -> Cost of Interco Sales | C9: ='F22'!C9 -> 5121 to 5139
A10: =A9+1 -> 6 | B10: ='F22'!B10 -> Total Cost of Sales | C10: ='F22'!C10 -> =SUM(C8:C9)
A11: =A10+1 -> 7 | B11: ='F22'!B11 -> Gross Profit | C11: ='F22'!C11 -> =C7+C10
A12: =A11+1 -> 8 | B12: ='F22'!B12 -> Commission/Mgt Income | C12: ='F22'!C12 -> 5501 to 5509
A13: =A12+1 -> 9 | B13: ='F22'!B13 -> Gain/(Loss) Disposal of FA | C13: ='F22'!C13 -> 9101
A14: =A13+1 -> 10 | B14: ='F22'!B14 -> Other Op Income | C14: ='F22'!C14 -> 5511 to 5599, 9001 to 9019, 9041Credit, 9102 to 9109Credit
A15: =A14+1 -> 11 | B15: ='F22'!B15 -> Other Op Expense | C15: ='F22'!C15 -> 5601 to 5999, 9041Debit, 9102 to 9109Debit, 9111 to 9115, 9117 to 9199
A16: =A15+1 -> 12 | B16: ='F22'!B16 -> Total Oth Op Income/ (Exp) | C16: ='F22'!C16 -> =SUM(C12:C15)
A17: =A16+1 -> 13 | B17: ='F22'!B17 -> Selling & Distribution | C17: ='F22'!C17 -> 7000 to 7999
... A31: =A30+1 -> 27 | B31: ='F22'!B31 -> Dividend Declared | C31: ='F22'!C31 -> 4902
B32: ='F22'!B32 -> Performance Indicators | D32: 42826 | E32: 42856 | F32: 42887 | G32: 42917 | H32: 42948 | I32: 42979 | J32: 43009 | K32: 43040 | L32: 43070 | M32: 43101 | N32: 43132 | O32: 43160 | P32: Total | Q32: FY 2017 | R32: Variance %
A33: 1 | B33: ='F22'!B33 -> Gross Profits Margin % | C33: ='F22'!C33 -> Gross Profits/Total Sales
A34: =A33+1 -> 2 | B34: ='F22'!B34 -> - External Sales GP % | C34: ='F22'!C34 -> (External Sales - Cost of External Sales)/External Sales
A35: =A34+1 -> 3 | B35: ='F22'!B35 -> - Interco Sales GP % | C35: ='F22'!C35 -> (Interco Sales - Cost of Interco Sales)/Interco Sales
A36: =A35+1 -> 4 | B36: ='F22'!B36 -> Selling & Dist Margin % | C36: ='F22'!C36 -> -Total S&D Exps/Total Sales
A37: =A36+1 -> 5 | B37: ='F22'!B37 -> A&G Margin Direct % | C37: ='F22'!C37 -> -Total Direct A&G Exps/Total Sales
A38: =A37+1 -> 6 | B38: ='F22'!B38 -> A&G Margin Total % | C38: ='F22'!C38 -> -Total A&G Exps/Total Sales
A39: =A38+1 -> 7 | B39: ='F22'!B39 -> Operating Profits Margin % | C39: ='F22'!C39 -> Profits from Operations/Total Sales
A40: =A39+1 -> 8 | B40: ='F22'!B40 -> Profits Before Taxation % | C40: ='F22'!C40 -> Profits Before Taxation/Total Sales
A41: =A40+1 -> 9 | B41: ='F22'!B41 -> Profit After Taxation % | C41: ='F22'!C41 -> Profits after Taxation/Total Sales

Sheet F23-Div
A1: LEEDEN NATIONAL OXYGEN LTD | D1: =F22S!D1 -> AS OF: 11-Oct-2017 | I1: =F21S!H1 -> FOR THE MONTH OF: Sep -17
A2: DIVISION: | D2: DEPT: | I2: SECTION:
A3: F23 P&L ACCOUNT BY DIV/DEPT/SEC/UNITS | D3: CURRENCY: SGD 000s | I3: FX: 0.00
D4: DIV 1 | E4: DIV 2 | F4: DIV 3 | G4: DIV 4 | H4: DIV 5 | I4: DIV 6 | J4: DIV 7 | K4: DIV 8 | L4: DIV 9 | M4: TOTAL
A5: 1 | B5: =F21R!B6 -> External Sales | C5: =F21R!C6 -> 5001 to 5029, 5051 to 5099
A6: =A5+1 -> 2 | B6: =F21R!B7 -> Interco Sales | C6: =F21R!C7 -> 5031 to 5049
A7: =A6+1 -> 3 | B7: =F21R!B8 -> Total Sales | C7: =SUM(C5:C6)
A8: =A7+1 -> 4 | B8: =F21R!B9 -> Cost of External Sales | C8: =F21R!C9 -> 5101 to 5119, 5141 to 5499, 6000 to 6999
A9: =A8+1 -> 5 | B9: =F21R!B10 -> Cost of Interco Sales | C9: =F21R!C10 -> 5121 to 5139
A10: =A9+1 -> 6 | B10: =F21R!B11 -> Total Cost of Sales | C10: =SUM(C8:C9)
A11: =A10+1 -> 7 | B11: =F21R!B12 -> Gross Profit | C11: =C7+C10
A12: =A11+1 -> 8 | B12: =F21R!B13 -> Commission/Mgt Income | C12: =F21R!C13 -> 5501 to 5509
A13: =A12+1 -> 9 | B13: =F21R!B14 -> Gain/(Loss) Disposal of FA | C13: =F21R!C14 -> 9101
A14: =A13+1 -> 10 | B14: =F21R!B15 -> Other Op Income | C14: =F21R!C15 -> 5511 to 5599, 9001 to 9019, 9041Credit, 9102 to 9109Credit
A15: =A14+1 -> 11 | B15: =F21R!B16 -> Other Op Expense | C15: =F21R!C16 -> 5601 to 5999, 9041Debit, 9102 to 9109Debit, 9111 to 9115, 9117 to 9199
A16: =A15+1 -> 12 | B16: =F21R!B17 -> Total Oth Op Income/ (Exp) | C16: =SUM(C12:C15)
A17: =A16+1 -> 13 | B17: =F21R!B18 -> Personnel Related Cost | C17: =F21R!C18 -> 7000 to 7099
A18: =A17+1 -> 14 | B18: =F21R!B19 -> Carriage/Transportation | C18: =F21R!C19 -> 7100 to 7199
A19: =A18+1 -> 15 | B19: =F21R!B20 -> Advertising/Promotion | C19: =F21R!C20 -> 7200 to 7299
A20: =A19+1 -> 16 | B20: =F21R!B21 -> Overseas Travelling | C20: =F21R!C21 -> 7301
A21: =A20+1 -> 17 | B21: =F21R!B22 -> Entertainment | C21: =F21R!C22 -> 7302 to 7399
A22: =A21+1 -> 18 | B22: =F21R!B23 -> Equipment Expenses | C22: =F21R!C23 -> 7400 to 7499
A23: =A22+1 -> 19 | B23: =F21R!B24 -> Rental/Property Related | C23: =F21R!C24 -> 7500 to 7599
A24: =A23+1 -> 20 | B24: =F21R!B25 -> Depn of Fixed Assets | C24: =F21R!C25 -> 7600 to 7699
A25: =A24+1 -> 21 | B25: =F21R!B26 -> Stationery/Printing/Telephone | C25: =F21R!C26 -> 7701 to 7705
A26: =A25+1 -> 22 | B26: =F21R!B27 -> HO/Interco and Other S&D | C26: =F21R!C27 -> 7706 to 7999
A27: =A26+1 -> 23 | B27: =F21R!B28 -> Total S&D Expenses | C27: =SUM(C17:C26)
A28: =A27+1 -> 24 | B28: =F21R!B29 -> Personnel Related Cost | C28: =F21R!C29 -> 8000 to 8099
A29: =A28+1 -> 25 | B29: =F21R!B30 -> Overseas Travelling | C29: =F21R!C30 -> 8101
A30: =A29+1 -> 26 | B30: =F21R!B31 -> Transportation | C30: =F21R!C31 -> 8102 to 8149
A31: =A30+1 -> 27 | B31: =F21R!B32 -> Entertainment & Donations | C31: =F21R!C32 -> 8150 to 8199
A32: =A31+1 -> 28 | B32: =F21R!B33 -> Equipment Expenses | C32: =F21R!C33 -> 8200 to 8299
A33: =A32+1 -> 29 | B33: =F21R!B34 -> Rental/Property Related | C33: =F21R!C34 -> 8300 to 8399
A34: =A33+1 -> 30 | B34: =F21R!B35 -> Depn of Fixed Assets | C34: =F21R!C35 -> 8400 to 8499
A35: =A34+1 -> 31 | B35: =F21R!B36 -> Stationery/Printing/Telephone | C35: =F21R!C36 -> 8500 to 8599
A36: =A35+1 -> 32 | B36: =F21R!B37 -> Legal/Prof Fees/Ins/Safety | C36: =F21R!C37 -> 8600 to 8649
A37: =A36+1 -> 33 | B37: =F21R!B38 -> IT System Exps | C37: =F21R!C38 -> 8651
A38: =A37+1 -> 34 | B38: =F21R!B39 -> Purchasing Exps | C38: =F21R!C39 -> 8653
A39: =A38+1 -> 35 | B39: =F21R!B40 -> A&G Direct Expenses | C39: =SUM(C28:C38)
A40: =A39+1 -> 36 | B40: =F21R!B41 -> Prov for Stock Obso/Pilferage | C40: =F21R!C41 -> 8701 to 8702
...

Sheet F23-Dep
A1: LEEDEN NATIONAL OXYGEN LTD | D1: AS OF: 11-Oct-2017 | I1: FOR THE MONTH OF: Sep -17
A2: DIVISION: WELDING & SAFETY | D2: DEPT: | I2: SECTION:
A3: ='F23-Div'!A3:B3 -> F23 P&L ACCOUNT BY DIV/DEPT/SEC/UNITS | D3: CURRENCY: SGD 000s | I3: FX: 0.00
D4: DEPT 1 | E4: DEPT 2 | F4: DEPT 3 | G4: DEPT 4 | H4: DEPT 5 | I4: DEPT 6 | J4: DEPT 7 | K4: DEPT 8 | L4: DEPT 9 | M4: TOTAL
A5: 1 | B5: ='F23-Div'!B5 -> External Sales | C5: ='F23-Div'!C5 -> 5001 to 5029, 5051 to 5099
A6: =A5+1 -> 2 | B6: ='F23-Div'!B6 -> Interco Sales | C6: ='F23-Div'!C6 -> 5031 to 5049
A7: =A6+1 -> 3 | B7: ='F23-Div'!B7 -> Total Sales | C7: ='F23-Div'!C7 -> =SUM(C5:C6)
A8: =A7+1 -> 4 | B8: ='F23-Div'!B8 -> Cost of External Sales | C8: ='F23-Div'!C8 -> 5101 to 5119, 5141 to 5499, 6000 to 6999
A9: =A8+1 -> 5 | B9: ='F23-Div'!B9 -> Cost of Interco Sales | C9: ='F23-Div'!C9 -> 5121 to 5139
A10: =A9+1 -> 6 | B10: ='F23-Div'!B10 -> Total Cost of Sales | C10: ='F23-Div'!C10 -> =SUM(C8:C9)
A11: =A10+1 -> 7 | B11: ='F23-Div'!B11 -> Gross Profit | C11: ='F23-Div'!C11 -> =C7+C10
A12: =A11+1 -> 8 | B12: ='F23-Div'!B12 -> Commission/Mgt Income | C12: ='F23-Div'!C12 -> 5501 to 5509
A13: =A12+1 -> 9 | B13: ='F23-Div'!B13 -> Gain/(Loss) Disposal of FA | C13: ='F23-Div'!C13 -> 9101
A14: =A13+1 -> 10 | B14: ='F23-Div'!B14 -> Other Op Income | C14: ='F23-Div'!C14 -> 5511 to 5599, 9001 to 9019, 9041Credit, 9102 to 9109Credit
A15: =A14+1 -> 11 | B15: ='F23-Div'!B15 -> Other Op Expense | C15: ='F23-Div'!C15 -> 5601 to 5999, 9041Debit, 9102 to 9109Debit, 9111 to 9115, 9117 to 9199
A16: =A15+1 -> 12 | B16: ='F23-Div'!B16 -> Total Oth Op Income/ (Exp) | C16: ='F23-Div'!C16 -> =SUM(C12:C15)
A17: =A16+1 -> 13 | B17: ='F23-Div'!B17 -> Personnel Related Cost | C17: ='F23-Div'!C17 -> 7000 to 7099
... A59: =A58+1 -> 55 | B59: ='F23-Div'!B59 -> Dividend Declared | C59: ='F23-Div'!C59 -> 4902
B60: ='F23-Div'!B60 -> Performance Indicators | D60: DEPT 1 | E60: DEPT 2 | F60: DEPT 3 | G60: DEPT 4 | H60: DEPT 5 | I60: DEPT 6 | J60: DEPT 7 | K60: DEPT 8 | L60: DEPT 9 | M60: TOTAL
A61: =A60+1 -> 1 | B61: ='F23-Div'!B61 -> Gross Profits Margin % | C61: ='F23-Div'!C61 -> Gross Profits/Total Sales
A62: =A61+1 -> 2 | B62: ='F23-Div'!B62 -> - External Sales GP % | C62: ='F23-Div'!C62 -> (External Sales - Cost of External Sales)/External Sales
A63: 3 | B63: ='F23-Div'!B63 -> - Interco Sales GP % | C63: ='F23-Div'!C63 -> (Interco Sales - Cost of Interco Sales)/Interco Sales
A64: 4 | B64: ='F23-Div'!B64 -> Selling & Dist Margin % | C64: ='F23-Div'!C64 -> -Total S&D Exps/Total Sales
A65: 5 | B65: ='F23-Div'!B65 -> A&G Margin Direct % | C65: ='F23-Div'!C65 -> -Total Direct A&G Exps/Total Sales
A66: 6 | B66: ='F23-Div'!B66 -> A&G Margin Total % | C66: ='F23-Div'!C66 -> -Total A&G Exps/Total Sales
A67: 7 | B67: ='F23-Div'!B67 -> Operating Profit Margin % | C67: ='F23-Div'!C67 -> Profits from Operations/Total Sales
A68: 8 | B68: ='F23-Div'!B68 -> Profit Before Taxation % | C68: ='F23-Div'!C68 -> Profits Before Taxation/Total Sales
A69: 9 | B69: ='F23-Div'!B69 -> Profit After Taxation % | C69: ='F23-Div'!C69 -> Profits after Taxation/Total Sales

Sheet F23-Sec
A1: LEEDEN NATIONAL OXYGEN LTD | D1: ='F23-Dep'!D1:H1 -> AS OF: 11-Oct-2017 | I1: ='F23-Dep'!I1:M1 -> FOR THE MONTH OF: Sep -17
A2: DIVISION: WELDING & SAFETY | D2: DEPT: WELDING SALES/PRODUCTS | I2: SECTION:
A3: ='F23-Dep'!A3:B3 -> F23 P&L ACCOUNT BY DIV/DEPT/SEC/UNITS | D3: CURRENCY: SGD 000s | I3: FX: 0.00
D4: SECT 1 | E4: SECT 2 | F4: SECT 3 | G4: SECT 4 | H4: SECT 5 | I4: SECT 6 | J4: SECT 7 | K4: SECT 8 | L4: SECT 9 | M4: TOTAL
A5: 1 | B5: ='F23-Dep'!B5 -> External Sales | C5: ='F23-Dep'!C5 -> 5001 to 5029, 5051 to 5099
A6: =A5+1 -> 2 | B6: ='F23-Dep'!B6 -> Interco Sales | C6: ='F23-Dep'!C6 -> 5031 to 5049
A7: =A6+1 -> 3 | B7: ='F23-Dep'!B7 -> Total Sales | C7: ='F23-Dep'!C7 -> =SUM(C5:C6)
A8: =A7+1 -> 4 | B8: ='F23-Dep'!B8 -> Cost of External Sales | C8: ='F23-Dep'!C8 -> 5101 to 5119, 5141 to 5499, 6000 to 6999
A9: =A8+1 -> 5 | B9: ='F23-Dep'!B9 -> Cost of Interco Sales | C9: ='F23-Dep'!C9 -> 5121 to 5139
A10: =A9+1 -> 6 | B10: ='F23-Dep'!B10 -> Total Cost of Sales | C10: ='F23-Dep'!C10 -> =SUM(C8:C9)
A11: =A10+1 -> 7 | B11: ='F23-Dep'!B11 -> Gross Profit | C11: ='F23-Dep'!C11 -> =C7+C10
A12: =A11+1 -> 8 | B12: ='F23-Dep'!B12 -> Commission/Mgt Income | C12: ='F23-Dep'!C12 -> 5501 to 5509
A13: =A12+1 -> 9 | B13: ='F23-Dep'!B13 -> Gain/(Loss) Disposal of FA | C13: ='F23-Dep'!C13 -> 9101
A14: =A13+1 -> 10 | B14: ='F23-Dep'!B14 -> Other Op Income | C14: ='F23-Dep'!C14 -> 5511 to 5599, 9001 to 9019, 9041Credit, 9102 to 9109Credit
A15: =A14+1 -> 11 | B15: ='F23-Dep'!B15 -> Other Op Expense | C15: ='F23-Dep'!C15 -> 5601 to 5999, 9041Debit, 9102 to 9109Debit, 9111 to 9115, 9117 to 9199
A16: =A15+1 -> 12 | B16: ='F23-Dep'!B16 -> Total Oth Op Income/ (Exp) | C16: ='F23-Dep'!C16 -> =SUM(C12:C15)
A17: =A16+1 -> 13 | B17: ='F23-Dep'!B17 -> Personnel Related Cost | C17: ='F23-Dep'!C17 -> 7000 to 7099
... A59: =A58+1 -> 55 | B59: ='F23-Dep'!B59 -> Dividend Declared | C59: ='F23-Dep'!C59 -> 4902
B60: ='F23-Dep'!B60 -> Performance Indicators | D60: SECT 1 | E60: SECT 2 | F60: SECT 3 | G60: SECT 4 | H60: SECT 5 | I60: SECT 6 | J60: SECT 7 | K60: SECT 8 | L60: SECT 9 | M60: TOTAL
A61: =A60+1 -> 1 | B61: ='F23-Dep'!B61 -> Gross Profits Margin % | C61: ='F23-Dep'!C61 -> Gross Profits/Total Sales
A62: =A61+1 -> 2 | B62: ='F23-Dep'!B62 -> - External Sales GP % | C62: ='F23-Dep'!C62 -> (External Sales - Cost of External Sales)/External Sales
A63: 3 | B63: ='F23-Dep'!B63 -> - Interco Sales GP % | C63: ='F23-Dep'!C63 -> (Interco Sales - Cost of Interco Sales)/Interco Sales
A64: 4 | B64: ='F23-Dep'!B64 -> Selling & Dist Margin % | C64: ='F23-Dep'!C64 -> -Total S&D Exps/Total Sales
A65: 5 | B65: ='F23-Dep'!B65 -> A&G Margin Direct % | C65: ='F23-Dep'!C65 -> -Total Direct A&G Exps/Total Sales
A66: 6 | B66: ='F23-Dep'!B66 -> A&G Margin Total % | C66: ='F23-Dep'!C66 -> -Total A&G Exps/Total Sales
A67: 7 | B67: ='F23-Dep'!B67 -> Operating Profit Margin % | C67: ='F23-Dep'!C67 -> Profits from Operations/Total Sales
A68: 8 | B68: ='F23-Dep'!B68 -> Profit Before Taxation % | C68: ='F23-Dep'!C68 -> Profits Before Taxation/Total Sales
A69: 9 | B69: ='F23-Dep'!B69 -> Profit After Taxation % | C69: ='F23-Dep'!C69 -> Profits after Taxation/Total Sales

Sheet F23-Units
A1: LEEDEN NATIONAL OXYGEN LTD | D1: ='F23-Dep'!D1:H1 -> AS OF: 11-Oct-2017 | I1: ='F23-Dep'!I1:M1 -> FOR THE MONTH OF: Sep -17
A2: DIVISION: GAS | D2: DEPT: PACKAGED GAS PRODUCTION | I2: SECTION: | J2: REFILLING
A3: ='F23-Dep'!A3:B3 -> F23 P&L ACCOUNT BY DIV/DEPT/SEC/UNITS | D3: CURRENCY: SGD 000s | I3: FX: 0.00
D4: UNIT 1 | E4: UNIT 2 | F4: UNIT 3 | G4: UNIT 4 | H4: UNIT 5 | I4: UNIT 6 | J4: UNIT 7 | K4: UNIT 8 | L4: UNIT 9 | M4: TOTAL
A5: 1 | B5: ='F23-Sec'!B5 -> External Sales | C5: ='F23-Sec'!C5 -> 5001 to 5029, 5051 to 5099
A6: =A5+1 -> 2 | B6: ='F23-Sec'!B6 -> Interco Sales | C6: ='F23-Sec'!C6 -> 5031 to 5049
A7: =A6+1 -> 3 | B7: ='F23-Sec'!B7 -> Total Sales | C7: ='F23-Sec'!C7 -> =SUM(C5:C6)
A8: =A7+1 -> 4 | B8: ='F23-Sec'!B8 -> Cost of External Sales | C8: ='F23-Sec'!C8 -> 5101 to 5119, 5141 to 5499, 6000 to 6999
A9: =A8+1 -> 5 | B9: ='F23-Sec'!B9 -> Cost of Interco Sales | C9: ='F23-Sec'!C9 -> 5121 to 5139
A10: =A9+1 -> 6 | B10: ='F23-Sec'!B10 -> Total Cost of Sales | C10: ='F23-Sec'!C10 -> =SUM(C8:C9)
A11: =A10+1 -> 7 | B11: ='F23-Sec'!B11 -> Gross Profit | C11: ='F23-Sec'!C11 -> =C7+C10
A12: =A11+1 -> 8 | B12: ='F23-Sec'!B12 -> Commission/Mgt Income | C12: ='F23-Sec'!C12 -> 5501 to 5509
A13: =A12+1 -> 9 | B13: ='F23-Sec'!B13 -> Gain/(Loss) Disposal of FA | C13: ='F23-Sec'!C13 -> 9101
A14: =A13+1 -> 10 | B14: ='F23-Sec'!B14 -> Other Op Income | C14: ='F23-Sec'!C14 -> 5511 to 5599, 9001 to 9019, 9041Credit, 9102 to 9109Credit
A15: =A14+1 -> 11 | B15: ='F23-Sec'!B15 -> Other Op Expense | C15: ='F23-Sec'!C15 -> 5601 to 5999, 9041Debit, 9102 to 9109Debit, 9111 to 9115, 9117 to 9199
A16: =A15+1 -> 12 | B16: ='F23-Sec'!B16 -> Total Oth Op Income/ (Exp) | C16: ='F23-Sec'!C16 -> =SUM(C12:C15)
A17: =A16+1 -> 13 | B17: ='F23-Sec'!B17 -> Personnel Related Cost | C17: ='F23-Sec'!C17 -> 7000 to 7099
... A59: =A58+1 -> 55 | B59: ='F23-Sec'!B59 -> Dividend Declared | C59: ='F23-Sec'!C59 -> 4902
B60: ='F23-Sec'!B60 -> Performance Indicators | D60: UNIT 1 | E60: UNIT 2 | F60: UNIT 3 | G60: UNIT 4 | H60: UNIT 5 | I60: UNIT 6 | J60: UNIT 7 | K60: UNIT 8 | L60: UNIT 9 | M60: TOTAL
A61: =A60+1 -> 1 | B61: ='F23-Sec'!B61 -> Gross Profits Margin % | C61: ='F23-Sec'!C61 -> Gross Profits/Total Sales
A62: =A61+1 -> 2 | B62: ='F23-Sec'!B62 -> - External Sales GP % | C62: ='F23-Sec'!C62 -> (External Sales - Cost of External Sales)/External Sales
A63: 3 | B63: ='F23-Sec'!B63 -> - Interco Sales GP % | C63: ='F23-Sec'!C63 -> (Interco Sales - Cost of Interco Sales)/Interco Sales
A64: 4 | B64: ='F23-Sec'!B64 -> Selling & Dist Margin % | C64: ='F23-Sec'!C64 -> -Total S&D Exps/Total Sales
A65: 5 | B65: ='F23-Sec'!B65 -> A&G Margin Direct % | C65: ='F23-Sec'!C65 -> -Total Direct A&G Exps/Total Sales
A66: 6 | B66: ='F23-Sec'!B66 -> A&G Margin Total % | C66: ='F23-Sec'!C66 -> -Total A&G Exps/Total Sales
A67: 7 | B67: ='F23-Sec'!B67 -> Operating Profit Margin % | C67: ='F23-Sec'!C67 -> Profits from Operations/Total Sales
A68: 8 | B68: ='F23-Sec'!B68 -> Profit Before Taxation % | C68: ='F23-Sec'!C68 -> Profits Before Taxation/Total Sales
A69: 9 | B69: ='F23-Sec'!B69 -> Profit After Taxation % | C69: ='F23-Sec'!C69 -> Profits after Taxation/Total Sales

Sheet F24
A1: LEEDEN NATIONAL OXYGEN LTD | D1: AS OF: 11-Oct-2017 | H1: FOR THE MONTH OF: Sep -17
A2: DIVISION: GAS | D2: DEPT: | H2: SECTION:
A3: F24 MANUFACTURING ACCOUNT | D3: CURRENCY: SGD 000s | H3: FX: 0.00
D4: CURRENT MONTH | H4: YEAR TO DATE
D5: Aug-17 | E5: Sep-17 | F5: Budget | G5: Variance | H5: Actual | I5: Budget | J5: Variance | K5: Last Year | L5: Variance
A6: 1 | B6: Manufacturing Costs
A7: =A6+1 -> 2 | B7: DM–Raw Materials | C7: 6101
A8: =A7+1 -> 3 | B8: DM–Parts & Access | C8: 6102
A9: =A8+1 -> 4 | B9: DM–Packing & Label Materials | C9: 6103 to 6104
A10: =A9+1 -> 5 | B10: DM–Others | C10: 6105 to 6199
A11: =A10+1 -> 6 | B11: Direct Material | C11: =SUM(C7:C10)
A12: =A11+1 -> 7 | B12: Salary & Leave | C12: 6201 to 6202
A13: =A12+1 -> 8 | B13: Bonus | C13: 6203 to 6204
A14: =A13+1 -> 9 | B14: Foreign Workers/Casual/Temp | C14: 6206, 6208
A15: =A14+1 -> 10 | B15: Overtime | C15: 6209 to 6210
A16: =A15+1 -> 11 | B16: Shift Allowance & Incentive | C16: 6205, 6211 to 6212
A17: =A16+1 -> 12 | B17: Staff Transport/Vehicle Rental | C17: 6213
A18: =A17+1 -> 13 | B18: Social Security Contribution | C18: 6214
A19: =A18+1 -> 14 | B19: Workers' Levy | C19: 6215
A20: =A19+1 -> 15 | B20: Others Direct Labor Costs | C20: 6207, 6216 to 6229
... A34: =A33+1 -> 29 | B34: Other Indirect Labor Costs | C34: 6315, 6323 to 6349
A35: =A34+1 -> 30 | B35: QA Allocated Cost
A36: =A35+1 -> 31 | B36: PM Allocated Cost
A37: =A36+1 -> 32 | B37: Indirect Labor | C37: =SUM(C25:C36)
A38: =A37+1 -> 33 | B38: Utilities - Elec, Water, Gas | C38: 6401 to 6410
A39: =A38+1 -> 34 | B39: Product Development/Testing | C39: 6421 to 6430
A40: =A39+1 -> 35 | B40: Carriage/Transport/Storage | C40: 6411 to 6420
A41: =A40+1 -> 36 | B41: Manufacturing Loss/Wastage | C41: 6431, 6432
A42: =A41+1 -> 37 | B42: Rejects/Reworks/Scrap | C42: 6433 to 6435
A43: =A42+1 -> 38 | B43: Disposal of Sludge/Others | C43: 6436 to 6499
A44: =A43+1 -> 39 | B44: QA Allocated Cost
A45: =A44+1 -> 40 | B45: PM Allocated Cost
A46: =A45+1 -> 41 | B46: Other Variable Overhead | C46: =SUM(C38:C45)
A47: =A46+1 -> 42 | B47: Total Variable Overhead | C47: =C24+C37+C46
A48: =A47+1 -> 43 | B48: Factory Rental/Upkeep | C48: 6501 to 6502, 6506
A49: =A48+1 -> 44 | B49: Property Tax for Factory | C49: 6503
A50: =A49+1 -> 45 | B50: Repair & Maintainance/Upkeep | C50: 6601 to 6620
A51: =A50+1 -> 46 | B51: Leasing of Mac&Equip/Vehicles/Cyl | C51: 6621 to 6623
A52: =A51+1 -> 47 | B52: Depreciation | C52: 6701 to 6749
A53: =A52+1 -> 48 | B53: Licenses & Insurance | C53: 6504, 6751 to 6759
...

Sheet F25-Div
A1: LEEDEN NATIONAL OXYGEN LTD | D1: ='F24'!D1:G1 -> AS OF: 11-Oct-2017 | I1: FOR THE MONTH OF: Sep -17
A2: DIVISION: | D2: DEPT: | I2: SECTION:
A3: F25 MANUFACTURING ACCOUNT | D3: CURRENCY: SGD 000s | I3: FX: 0.00
A4: BY DIV/DEPT/SEC/UNITS | D4: DIV 1 | E4: DIV 2 | F4: DIV 3 | G4: DIV 4 | H4: DIV 5 | I4: DIV 6 | J4: DIV 7 | K4: DIV 8 | L4: TOTAL
A5: 1 | B5: ='F24'!B6 -> Manufacturing Costs
A6: =A5+1 -> 2 | B6: ='F24'!B7 -> DM–Raw Materials | C6: ='F24'!C7 -> 6101
A7: =A6+1 -> 3 | B7: ='F24'!B8 -> DM–Parts & Access | C7: ='F24'!C8 -> 6102
A8: =A7+1 -> 4 | B8: ='F24'!B9 -> DM–Packing & Label Materials | C8: ='F24'!C9 -> 6103 to 6104
A9: =A8+1 -> 5 | B9: ='F24'!B10 -> DM–Others | C9: ='F24'!C10 -> 6105 to 6199
A10: =A9+1 -> 6 | B10: ='F24'!B11 -> Direct Material | C10: =SUM(C6:C9)
A11: =A10+1 -> 7 | B11: ='F24'!B12 -> Salary & Leave | C11: ='F24'!C12 -> 6201 to 6202
A12: =A11+1 -> 8 | B12: ='F24'!B13 -> Bonus | C12: ='F24'!C13 -> 6203 to 6204
A13: =A12+1 -> 9 | B13: ='F24'!B14 -> Foreign Workers/Casual/Temp | C13: ='F24'!C14 -> 6206, 6208
A14: =A13+1 -> 10 | B14: ='F24'!B15 -> Overtime | C14: ='F24'!C15 -> 6209 to 6210
A15: =A14+1 -> 11 | B15: ='F24'!B16 -> Shift Allowance & Incentive | C15: ='F24'!C16 -> 6205, 6211 to 6212
A16: =A15+1 -> 12 | B16: ='F24'!B17 -> Staff Transport/Vehicle Rental | C16: ='F24'!C17 -> 6213
A17: =A16+1 -> 13 | B17: ='F24'!B18 -> Social Security Contribution | C17: ='F24'!C18 -> 6214
A18: =A17+1 -> 14 | B18: ='F24'!B19 -> Workers' Levy | C18: ='F24'!C19 -> 6215
A19: =A18+1 -> 15 | B19: ='F24'!B20 -> Others Direct Labor Costs | C19: ='F24'!C20 -> 6207, 6216 to 6229
A20: =A19+1 -> 16 | B20: ='F24'!B21 -> Direct Labor | C20: =SUM(C11:C19)
A21: =A20+1 -> 17 | B21: ='F24'!B22 -> Direct Expenses | C21: ='F24'!C22 -> 6251 to 6299
A22: =A21+1 -> 18 | B22: ='F24'!B23 -> Prime Cost | C22: =C10+C20+C21
A23: =A22+1 -> 19 | B23: ='F24'!B24 -> Indirect Material | C23: ='F24'!C24 -> 6301 to 6310
A24: =A23+1 -> 20 | B24: ='F24'!B25 -> Salary & Leave | C24: ='F24'!C25 -> 6311
A25: =A24+1 -> 21 | B25: ='F24'!B26 -> Bonus | C25: ='F24'!C26 -> 6312
A26: =A25+1 -> 22 | B26: ='F24'!B27 -> Foreign Workers/Casual/Temp | C26: ='F24'!C27 -> 6314, 6316
A27: =A26+1 -> 23 | B27: ='F24'!B28 -> Overtime | C27: ='F24'!C28 -> 6317
A28: =A27+1 -> 24 | B28: ='F24'!B29 -> Shift Allowance & Incentive | C28: ='F24'!C29 -> 6313, 6318 to 6319
A29: =A28+1 -> 25 | B29: ='F24'!B30 -> Staff Transport/Vehicle Rental | C29: ='F24'!C30 -> 6320
A30: =A29+1 -> 26 | B30: ='F24'!B31 -> Social Security Contribution | C30: ='F24'!C31 -> 6321
A31: =A30+1 -> 27 | B31: ='F24'!B32 -> Workers' Levy | C31: ='F24'!C32 -> 6322
A32: =A31+1 -> 28 | B32: ='F24'!B33 -> Expats' Expenses | C32: ='F24'!C33 -> 6351 to 6399
A33: =A32+1 -> 29 | B33: ='F24'!B34 -> Other Indirect Labor Costs | C33: ='F24'!C34 -> 6315, 6323 to 6349
A34: =A33+1 -> 30 | B34: ='F24'!B35 -> QA Allocated Cost
A35: =A34+1 -> 31 | B35: ='F24'!B36 -> PM Allocated Cost
A36: =A35+1 -> 32 | B36: ='F24'!B37 -> Indirect Labor | C36: =SUM(C24:C35)
A37: =A36+1 -> 33 | B37: ='F24'!B38 -> Utilities - Elec, Water, Gas | C37: ='F24'!C38 -> 6401 to 6410
A38: =A37+1 -> 34 | B38: ='F24'!B39 -> Product Development/Testing | C38: ='F24'!C39 -> 6421 to 6430
A39: =A38+1 -> 35 | B39: ='F24'!B40 -> Carriage/Transport/Storage | C39: ='F24'!C40 -> 6411 to 6420
A40: =A39+1 -> 36 | B40: ='F24'!B41 -> Manufacturing Loss/Wastage | C40: ='F24'!C41 -> 6431, 6432
...

Sheet F25-Dep
A1: LEEDEN NATIONAL OXYGEN LTD | D1: ='F24'!D1:G1 -> AS OF: 11-Oct-2017 | I1: FOR THE MONTH OF: Sep -17
A2: DIVISION: GAS | D2: DEPT: | I2: SECTION:
A3: ='F25-Div'!A3:B3 -> F25 MANUFACTURING ACCOUNT | D3: CURRENCY: SGD 000s | I3: FX: 0.00
A4: ='F25-Div'!A4:B4 -> BY DIV/DEPT/SEC/UNITS | D4: DEPT 1 | E4: DEPT 2 | F4: DEPT 3 | G4: DEPT 4 | H4: DEPT 5 | I4: DEPT 6 | J4: DEPT 7 | K4: DEPT 8 | L4: TOTAL
A5: 1 | B5: ='F25-Div'!B5 -> Manufacturing Costs
A6: =A5+1 -> 2 | B6: ='F25-Div'!B6 -> DM–Raw Materials | C6: ='F25-Div'!C6 -> 6101
A7: =A6+1 -> 3 | B7: ='F25-Div'!B7 -> DM–Parts & Access | C7: ='F25-Div'!C7 -> 6102
A8: =A7+1 -> 4 | B8: ='F25-Div'!B8 -> DM–Packing & Label Materials | C8: ='F25-Div'!C8 -> 6103 to 6104
A9: =A8+1 -> 5 | B9: ='F25-Div'!B9 -> DM–Others | C9: ='F25-Div'!C9 -> 6105 to 6199
A10: =A9+1 -> 6 | B10: ='F25-Div'!B10 -> Direct Material | C10: ='F25-Div'!C10 -> =SUM(C6:C9)
A11: =A10+1 -> 7 | B11: ='F25-Div'!B11 -> Salary & Leave | C11: ='F25-Div'!C11 -> 6201 to 6202
A12: =A11+1 -> 8 | B12: ='F25-Div'!B12 -> Bonus | C12: ='F25-Div'!C12 -> 6203 to 6204
A13: =A12+1 -> 9 | B13: ='F25-Div'!B13 -> Foreign Workers/Casual/Temp | C13: ='F25-Div'!C13 -> 6206, 6208
A14: =A13+1 -> 10 | B14: ='F25-Div'!B14 -> Overtime | C14: ='F25-Div'!C14 -> 6209 to 6210
A15: =A14+1 -> 11 | B15: ='F25-Div'!B15 -> Shift Allowance & Incentive | C15: ='F25-Div'!C15 -> 6205, 6211 to 6212
A16: =A15+1 -> 12 | B16: ='F25-Div'!B16 -> Staff Transport/Vehicle Rental | C16: ='F25-Div'!C16 -> 6213
A17: =A16+1 -> 13 | B17: ='F25-Div'!B17 -> Social Security Contribution | C17: ='F25-Div'!C17 -> 6214
... A33: =A32+1 -> 29 | B33: ='F25-Div'!B33 -> Other Indirect Labor Costs | C33: ='F25-Div'!C33 -> 6315, 6323 to 6349
A34: =A33+1 -> 30 | B34: ='F25-Div'!B34 -> QA Allocated Cost
A35: =A34+1 -> 31 | B35: ='F25-Div'!B35 -> PM Allocated Cost
A36: =A35+1 -> 32 | B36: ='F25-Div'!B36 -> Indirect Labor | C36: ='F25-Div'!C36 -> =SUM(C24:C35)
A37: =A36+1 -> 33 | B37: ='F25-Div'!B37 -> Utilities - Elec, Water, Gas | C37: ='F25-Div'!C37 -> 6401 to 6410
A38: =A37+1 -> 34 | B38: ='F25-Div'!B38 -> Product Development/Testing | C38: ='F25-Div'!C38 -> 6421 to 6430
A39: =A38+1 -> 35 | B39: ='F25-Div'!B39 -> Carriage/Transport/Storage | C39: ='F25-Div'!C39 -> 6411 to 6420
A40: =A39+1 -> 36 | B40: ='F25-Div'!B40 -> Manufacturing Loss/Wastage | C40: ='F25-Div'!C40 -> 6431, 6432
A41: =A40+1 -> 37 | B41: ='F25-Div'!B41 -> Rejects/Reworks/Scrap | C41: ='F25-Div'!C41 -> 6433 to 6435
A42: =A41+1 -> 38 | B42: ='F25-Div'!B42 -> Disposal of Sludge/Others | C42: ='F25-Div'!C42 -> 6436 to 6499
A43: =A42+1 -> 39 | B43: ='F25-Div'!B43 -> QA Allocated Cost
A44: =A43+1 -> 40 | B44: ='F25-Div'!B44 -> PM Allocated Cost
A45: =A44+1 -> 41 | B45: ='F25-Div'!B45 -> Other Variable Overhead | C45: =SUM(C37:C44)
A46: =A45+1 -> 42 | B46: ='F25-Div'!B46 -> Total Variable Overhead | C46: ='F25-Div'!C46 -> =C23+C36+c45
A47: =A46+1 -> 43 | B47: ='F25-Div'!B47 -> Factory Rental/Upkeep | C47: ='F25-Div'!C47 -> 6501 to 6502, 6506
A48: =A47+1 -> 44 | B48: ='F25-Div'!B48 -> Property Tax for Factory | C48: ='F25-Div'!C48 -> 6503
A49: =A48+1 -> 45 | B49: ='F25-Div'!B49 -> Repair & Maintainance/Upkeep | C49: ='F25-Div'!C49 -> 6601 to 6620
A50: =A49+1 -> 46 | B50: ='F25-Div'!B50 -> Leasing of Mac&Equip/Vehicles/Cyl | C50: ='F25-Div'!C50 -> 6621 to 6623
A51: =A50+1 -> 47 | B51: ='F25-Div'!B51 -> Depreciation | C51: ='F25-Div'!C51 -> 6701 to 6749
A52: =A51+1 -> 48 | B52: ='F25-Div'!B52 -> Licenses & Insurance | C52: ='F25-Div'!C52 -> 6504, 6751 to 6759
A53: =A52+1 -> 49 | B53: ='F25-Div'!B53 -> Non Capitalised Purchases | C53: ='F25-Div'!C53 -> 6761 to 6769
A54: =A53+1 -> 50 | B54: ='F25-Div'!B54 -> Others Fixed Overhead | C54: ='F25-Div'!C54 -> 6505, 6771 to 6799
A55: =A54+1 -> 51 | B55: ='F25-Div'!B55 -> QA Allocated Cost
...

Sheet F25-Sec
A1: LEEDEN NATIONAL OXYGEN LTD | D1: ='F25-Div'!D1:H1 -> AS OF: 11-Oct-2017 | I1: ='F25-Div'!I1:L1 -> FOR THE MONTH OF: Sep -17
A2: ='F25-Dep'!A2 -> DIVISION: GAS | D2: DEPT: | E2: PACKAGED GAS PRODUCTION | I2: SECTION:
A3: ='F25-Dep'!A3:B3 -> F25 MANUFACTURING ACCOUNT | D3: CURRENCY: SGD 000s | I3: FX: 0.00
A4: ='F25-Div'!A4:B4 -> BY DIV/DEPT/SEC/UNITS | D4: SECT 1 | E4: SECT 2 | F4: SECT 3 | G4: SECT 4 | H4: SECT 5 | I4: SECT 6 | J4: SECT 7 | K4: SECT 8 | L4: TOTAL
A5: 1 | B5: ='F25-Dep'!B5 -> Manufacturing Costs
A6: =A5+1 -> 2 | B6: ='F25-Dep'!B6 -> DM–Raw Materials | C6: ='F25-Dep'!C6 -> 6101
A7: =A6+1 -> 3 | B7: ='F25-Dep'!B7 -> DM–Parts & Access | C7: ='F25-Dep'!C7 -> 6102
A8: =A7+1 -> 4 | B8: ='F25-Dep'!B8 -> DM–Packing & Label Materials | C8: ='F25-Dep'!C8 -> 6103 to 6104
A9: =A8+1 -> 5 | B9: ='F25-Dep'!B9 -> DM–Others | C9: ='F25-Dep'!C9 -> 6105 to 6199
A10: =A9+1 -> 6 | B10: ='F25-Dep'!B10 -> Direct Material | C10: ='F25-Dep'!C10 -> =SUM(C6:C9)
A11: =A10+1 -> 7 | B11: ='F25-Dep'!B11 -> Salary & Leave | C11: ='F25-Dep'!C11 -> 6201 to 6202
A12: =A11+1 -> 8 | B12: ='F25-Dep'!B12 -> Bonus | C12: ='F25-Dep'!C12 -> 6203 to 6204
A13: =A12+1 -> 9 | B13: ='F25-Dep'!B13 -> Foreign Workers/Casual/Temp | C13: ='F25-Dep'!C13 -> 6206, 6208
A14: =A13+1 -> 10 | B14: ='F25-Dep'!B14 -> Overtime | C14: ='F25-Dep'!C14 -> 6209 to 6210
A15: =A14+1 -> 11 | B15: ='F25-Dep'!B15 -> Shift Allowance & Incentive | C15: ='F25-Dep'!C15 -> 6205, 6211 to 6212
A16: =A15+1 -> 12 | B16: ='F25-Dep'!B16 -> Staff Transport/Vehicle Rental | C16: ='F25-Dep'!C16 -> 6213
A17: =A16+1 -> 13 | B17: ='F25-Dep'!B17 -> Social Security Contribution | C17: ='F25-Dep'!C17 -> 6214
... A33: =A32+1 -> 29 | B33: ='F25-Dep'!B33 -> Other Indirect Labor Costs | C33: ='F25-Dep'!C33 -> 6315, 6323 to 6349
A34: =A33+1 -> 30 | B34: ='F25-Dep'!B34 -> QA Allocated Cost
A35: =A34+1 -> 31 | B35: ='F25-Dep'!B35 -> PM Allocated Cost
A36: =A35+1 -> 32 | B36: ='F25-Dep'!B36 -> Indirect Labor | C36: ='F25-Dep'!C36 -> =SUM(C24:C35)
A37: =A36+1 -> 33 | B37: ='F25-Dep'!B37 -> Utilities - Elec, Water, Gas | C37: ='F25-Dep'!C37 -> 6401 to 6410
A38: =A37+1 -> 34 | B38: ='F25-Dep'!B38 -> Product Development/Testing | C38: ='F25-Dep'!C38 -> 6421 to 6430
A39: =A38+1 -> 35 | B39: ='F25-Dep'!B39 -> Carriage/Transport/Storage | C39: ='F25-Dep'!C39 -> 6411 to 6420
A40: =A39+1 -> 36 | B40: ='F25-Dep'!B40 -> Manufacturing Loss/Wastage | C40: ='F25-Dep'!C40 -> 6431, 6432
A41: =A40+1 -> 37 | B41: ='F25-Dep'!B41 -> Rejects/Reworks/Scrap | C41: ='F25-Dep'!C41 -> 6433 to 6435
A42: =A41+1 -> 38 | B42: ='F25-Dep'!B42 -> Disposal of Sludge/Others | C42: ='F25-Dep'!C42 -> 6436 to 6499
A43: =A42+1 -> 39 | B43: ='F25-Dep'!B43 -> QA Allocated Cost
A44: =A43+1 -> 40 | B44: ='F25-Dep'!B44 -> PM Allocated Cost
A45: =A44+1 -> 41 | B45: ='F25-Dep'!B45 -> Other Variable Overhead | C45: =SUM(C37:C44)
A46: =A45+1 -> 42 | B46: ='F25-Dep'!B46 -> Total Variable Overhead | C46: ='F25-Dep'!C46 -> =C23+C36+c45
A47: =A46+1 -> 43 | B47: ='F25-Dep'!B47 -> Factory Rental/Upkeep | C47: ='F25-Dep'!C47 -> 6501 to 6502, 6506
A48: =A47+1 -> 44 | B48: ='F25-Dep'!B48 -> Property Tax for Factory | C48: ='F25-Dep'!C48 -> 6503
A49: =A48+1 -> 45 | B49: ='F25-Dep'!B49 -> Repair & Maintainance/Upkeep | C49: ='F25-Dep'!C49 -> 6601 to 6620
A50: =A49+1 -> 46 | B50: ='F25-Dep'!B50 -> Leasing of Mac&Equip/Vehicles/Cyl | C50: ='F25-Dep'!C50 -> 6621 to 6623
A51: =A50+1 -> 47 | B51: ='F25-Dep'!B51 -> Depreciation | C51: ='F25-Dep'!C51 -> 6701 to 6749
A52: =A51+1 -> 48 | B52: ='F25-Dep'!B52 -> Licenses & Insurance | C52: ='F25-Dep'!C52 -> 6504, 6751 to 6759
A53: =A52+1 -> 49 | B53: ='F25-Dep'!B53 -> Non Capitalised Purchases | C53: ='F25-Dep'!C53 -> 6761 to 6769
A54: =A53+1 -> 50 | B54: ='F25-Dep'!B54 -> Others Fixed Overhead | C54: ='F25-Dep'!C54 -> 6505, 6771 to 6799
A55: =A54+1 -> 51 | B55: ='F25-Dep'!B55 -> QA Allocated Cost
...

Sheet F25-Units
A1: LEEDEN NATIONAL OXYGEN LTD | D1: ='F25-Div'!D1:H1 -> AS OF: 11-Oct-2017 | I1: ='F25-Div'!I1:L1 -> FOR THE MONTH OF: Sep -17
A2: ='F25-Sec'!A2 -> DIVISION: GAS | D2: DEPT: | E2: PACKAGED GAS PRODUCTION | I2: SECTION: REFILLING
A3: ='F25-Sec'!A3:B3 -> F25 MANUFACTURING ACCOUNT | D3: CURRENCY: SGD 000s | I3: FX: 0.00
A4: ='F25-Div'!A4:B4 -> BY DIV/DEPT/SEC/UNITS | D4: UNIT 1 | E4: UNIT 2 | F4: UNIT 3 | G4: UNIT 4 | H4: UNIT 5 | I4: UNIT 6 | J4: UNIT 7 | K4: UNIT 8 | L4: TOTAL
A5: 1 | B5: ='F25-Sec'!B5 -> Manufacturing Costs
A6: =A5+1 -> 2 | B6: ='F25-Sec'!B6 -> DM–Raw Materials | C6: ='F25-Sec'!C6 -> 6101
A7: =A6+1 -> 3 | B7: ='F25-Sec'!B7 -> DM–Parts & Access | C7: ='F25-Sec'!C7 -> 6102
A8: =A7+1 -> 4 | B8: ='F25-Sec'!B8 -> DM–Packing & Label Materials | C8: ='F25-Sec'!C8 -> 6103 to 6104
A9: =A8+1 -> 5 | B9: ='F25-Sec'!B9 -> DM–Others | C9: ='F25-Sec'!C9 -> 6105 to 6199
A10: =A9+1 -> 6 | B10: ='F25-Sec'!B10 -> Direct Material | C10: ='F25-Sec'!C10 -> =SUM(C6:C9)
A11: =A10+1 -> 7 | B11: ='F25-Sec'!B11 -> Salary & Leave | C11: ='F25-Sec'!C11 -> 6201 to 6202
A12: =A11+1 -> 8 | B12: ='F25-Sec'!B12 -> Bonus | C12: ='F25-Sec'!C12 -> 6203 to 6204
A13: =A12+1 -> 9 | B13: ='F25-Sec'!B13 -> Foreign Workers/Casual/Temp | C13: ='F25-Sec'!C13 -> 6206, 6208
A14: =A13+1 -> 10 | B14: ='F25-Sec'!B14 -> Overtime | C14: ='F25-Sec'!C14 -> 6209 to 6210
A15: =A14+1 -> 11 | B15: ='F25-Sec'!B15 -> Shift Allowance & Incentive | C15: ='F25-Sec'!C15 -> 6205, 6211 to 6212
A16: =A15+1 -> 12 | B16: ='F25-Sec'!B16 -> Staff Transport/Vehicle Rental | C16: ='F25-Sec'!C16 -> 6213
A17: =A16+1 -> 13 | B17: ='F25-Sec'!B17 -> Social Security Contribution | C17: ='F25-Sec'!C17 -> 6214
... A33: =A32+1 -> 29 | B33: ='F25-Sec'!B33 -> Other Indirect Labor Costs | C33: ='F25-Sec'!C33 -> 6315, 6323 to 6349
A34: =A33+1 -> 30 | B34: ='F25-Sec'!B34 -> QA Allocated Cost
A35: =A34+1 -> 31 | B35: ='F25-Sec'!B35 -> PM Allocated Cost
A36: =A35+1 -> 32 | B36: ='F25-Sec'!B36 -> Indirect Labor | C36: ='F25-Sec'!C36 -> =SUM(C24:C35)
A37: =A36+1 -> 33 | B37: ='F25-Sec'!B37 -> Utilities - Elec, Water, Gas | C37: ='F25-Sec'!C37 -> 6401 to 6410
A38: =A37+1 -> 34 | B38: ='F25-Sec'!B38 -> Product Development/Testing | C38: ='F25-Sec'!C38 -> 6421 to 6430
A39: =A38+1 -> 35 | B39: ='F25-Sec'!B39 -> Carriage/Transport/Storage | C39: ='F25-Sec'!C39 -> 6411 to 6420
A40: =A39+1 -> 36 | B40: ='F25-Sec'!B40 -> Manufacturing Loss/Wastage | C40: ='F25-Sec'!C40 -> 6431, 6432
A41: =A40+1 -> 37 | B41: ='F25-Sec'!B41 -> Rejects/Reworks/Scrap | C41: ='F25-Sec'!C41 -> 6433 to 6435
A42: =A41+1 -> 38 | B42: ='F25-Sec'!B42 -> Disposal of Sludge/Others | C42: ='F25-Sec'!C42 -> 6436 to 6499
A43: =A42+1 -> 39 | B43: ='F25-Sec'!B43 -> QA Allocated Cost
A44: =A43+1 -> 40 | B44: ='F25-Sec'!B44 -> PM Allocated Cost
A45: =A44+1 -> 41 | B45: ='F25-Sec'!B45 -> Other Variable Overhead | C45: =SUM(C37:C44)
A46: =A45+1 -> 42 | B46: ='F25-Sec'!B46 -> Total Variable Overhead | C46: ='F25-Sec'!C46 -> =C23+C36+c45
A47: =A46+1 -> 43 | B47: ='F25-Sec'!B47 -> Factory Rental/Upkeep | C47: ='F25-Sec'!C47 -> 6501 to 6502, 6506
A48: =A47+1 -> 44 | B48: ='F25-Sec'!B48 -> Property Tax for Factory | C48: ='F25-Sec'!C48 -> 6503
A49: =A48+1 -> 45 | B49: ='F25-Sec'!B49 -> Repair & Maintainance/Upkeep | C49: ='F25-Sec'!C49 -> 6601 to 6620
A50: =A49+1 -> 46 | B50: ='F25-Sec'!B50 -> Leasing of Mac&Equip/Vehicles/Cyl | C50: ='F25-Sec'!C50 -> 6621 to 6623
A51: =A50+1 -> 47 | B51: ='F25-Sec'!B51 -> Depreciation | C51: ='F25-Sec'!C51 -> 6701 to 6749
A52: =A51+1 -> 48 | B52: ='F25-Sec'!B52 -> Licenses & Insurance | C52: ='F25-Sec'!C52 -> 6504, 6751 to 6759
A53: =A52+1 -> 49 | B53: ='F25-Sec'!B53 -> Non Capitalised Purchases | C53: ='F25-Sec'!C53 -> 6761 to 6769
A54: =A53+1 -> 50 | B54: ='F25-Sec'!B54 -> Others Fixed Overhead | C54: ='F25-Sec'!C54 -> 6505, 6771 to 6799
A55: =A54+1 -> 51 | B55: ='F25-Sec'!B55 -> QA Allocated Cost
...

Sheet F26M
A1: LEEDEN NATIONAL OXYGEN LTD | D1: ='F25-Div'!D1:H1 -> AS OF: 11-Oct-2017 | I1: ='F25-Div'!I1:L1 -> FOR THE MONTH OF: Sep -17
A2: DEPT: IGP | D2: SECTION: ASPs | I2: UNIT: ASP2
A3: F26M ASU MANUFACTURING ACCOUNT | D3: CURRENCY: SGD 000s | I3: FX: 0.00
A4: BY PRODUCTS BY MONTH | D4: GO | E4: LO | F4: GN | G4: LN | H4: LAR | L4: TOTAL
A5: 1 | B5: Budget Production (M3 / KG)
A6: =A5+1 -> 2 | B6: Actual Production (M3 / KG)
A7: =A6+1 -> 3 | B7: Variance (M3 / KG)
A9: 4 | B9: Allocation Factors
A11: ACTUAL | B11: Budget
D12: GO | E12: LO | F12: GN | G12: LN | H12: LAR | L12: TOTAL
A13: 1 | B13: Direct Expenses -Electricity
A14: =A13+1 -> 2 | B14: Direct Labor
A15: =A14+1 -> 3 | B15: Prime Cost
A16: =A15+1 -> 4 | B16: Indirect Labor
A17: =A16+1 -> 5 | B17: Other Variable Overhead
A18: =A17+1 -> 6 | B18: Total Variable Overhead
A19: =A18+1 -> 7 | B19: Fixed Overhead
A20: =A19+1 -> 8 | B20: Cost of Goods Manufactured
B21: Cost Indicators :
A22: 1 | B22: Direct Exps (m3 / Kg) | C22: Direct Expenses/Actual Production Volume
A23: =A22+1 -> 2 | B23: Direct Labour (m3 / Kg) | C23: Direct Labour/Actual Production Volume
A24: =A23+1 -> 3 | B24: Indirect Labour (m3 / Kg) | C24: Indirect Labour/Actual Production Volume
A25: =A24+1 -> 4 | B25: Variable Overhead (m3 / Kg) | C25: Variable Overhead/Actual Production Volume
A26: =A25+1 -> 5 | B26: Total Variable (m3 / Kg) | C26: Total Variable/Actual Production Volume
A27: =A26+1 -> 6 | B27: Fixed Overhead (m3 / Kg) | C27: Fixed Overhead/Actual Production Volume
A28: =A27+1 -> 7 | B28: Manufacturing Costs (m3/ Kg) | C28: Manufacturing Costs/Actual Production Volume
A30: BUDGET | B30: Budget
D31: GO | E31: LO | F31: GN | G31: LN | H31: LAR | L31: TOTAL
A32: 1 | B32: Direct Expenses -Electricity
A33: =A32+1 -> 2 | B33: Direct Labor
A34: =A33+1 -> 3 | B34: Prime Cost
A35: =A34+1 -> 4 | B35: Indirect Labor
A36: =A35+1 -> 5 | B36: Other Variable Overhead
A37: =A36+1 -> 6 | B37: Total Variable Overhead
A38: =A37+1 -> 7 | B38: Fixed Overhead
A39: =A38+1 -> 8 | B39: Cost of Goods Manufactured
B40: Cost Indicators :
A41: 1 | B41: Direct Exps (m3 / Kg) | C41: =C22 -> Direct Expenses/Actual Production Volume
A42: =A41+1 -> 2 | B42: Direct Labour (m3 / Kg) | C42: =C23 -> Direct Labour/Actual Production Volume
A43: =A42+1 -> 3 | B43: Indirect Labour (m3 / Kg) | C43: =C24 -> Indirect Labour/Actual Production Volume
...

Sheet F26Y
A1: LEEDEN NATIONAL OXYGEN LTD | D1: ='F25-Div'!D1:H1 -> AS OF: 11-Oct-2017 | I1: ='F25-Div'!I1:L1 -> FOR THE MONTH OF: Sep -17
A2: DEPT: IGP | D2: SECTION: ASPs | I2: UNIT: ASP2
A3: F26Y ASU MANUFACTURING ACCOUNT | D3: CURRENCY: SGD 000s | I3: FX: 0.00
A4: BY PRODUCTS YEAR TO DATE | D4: GO | E4: LO | F4: GN | G4: LN | H4: LAR | L4: TOTAL
A5: 1 | B5: Budget Production (M3 / KG)
A6: =A5+1 -> 2 | B6: Actual Production (M3 / KG)
A7: =A6+1 -> 3 | B7: Variance (M3 / KG)
A9: 4 | B9: Allocation Factors
A11: ACTUAL | B11: Budget
D12: GO | E12: LO | F12: GN | G12: LN | H12: LAR | L12: TOTAL
A13: 1 | B13: Direct Expenses -Electricity
A14: =A13+1 -> 2 | B14: Direct Labor
A15: =A14+1 -> 3 | B15: Prime Cost
A16: =A15+1 -> 4 | B16: Indirect Labor
A17: =A16+1 -> 5 | B17: Other Variable Overhead
A18: =A17+1 -> 6 | B18: Total Variable Overhead
A19: =A18+1 -> 7 | B19: Fixed Overhead
A20: =A19+1 -> 8 | B20: Cost of Goods Manufactured
B21: Cost Indicators :
A22: 1 | B22: Direct Exps (m3 / Kg) | C22: =F26M!C22 -> Direct Expenses/Actual Production Volume
A23: =A22+1 -> 2 | B23: Direct Labour (m3 / Kg) | C23: =F26M!C23 -> Direct Labour/Actual Production Volume
A24: =A23+1 -> 3 | B24: Indirect Labour (m3 / Kg) | C24: =F26M!C24 -> Indirect Labour/Actual Production Volume
A25: =A24+1 -> 4 | B25: Variable Overhead (m3 / Kg) | C25: =F26M!C25 -> Variable Overhead/Actual Production Volume
A26: =A25+1 -> 5 | B26: Total Variable (m3 / Kg) | C26: =F26M!C26 -> Total Variable/Actual Production Volume
A27: =A26+1 -> 6 | B27: Fixed Overhead (m3 / Kg) | C27: =F26M!C27 -> Fixed Overhead/Actual Production Volume
A28: =A27+1 -> 7 | B28: Manufacturing Costs (m3/ Kg) | C28: =F26M!C28 -> Manufacturing Costs/Actual Production Volume
A30: BUDGET | B30: Budget
D31: GO | E31: LO | F31: GN | G31: LN | H31: LAR | L31: TOTAL
A32: 1 | B32: Direct Expenses -Electricity
A33: =A32+1 -> 2 | B33: Direct Labor
A34: =A33+1 -> 3 | B34: Prime Cost
A35: =A34+1 -> 4 | B35: Indirect Labor
A36: =A35+1 -> 5 | B36: Other Variable Overhead
A37: =A36+1 -> 6 | B37: Total Variable Overhead
A38: =A37+1 -> 7 | B38: Fixed Overhead
A39: =A38+1 -> 8 | B39: Cost of Goods Manufactured
B40: Cost Indicators :
A41: 1 | B41: Direct Exps (m3 / Kg) | C41: =F26M!C41 -> Direct Expenses/Actual Production Volume
A42: =A41+1 -> 2 | B42: Direct Labour (m3 / Kg) | C42: =F26M!C42 -> Direct Labour/Actual Production Volume
A43: =A42+1 -> 3 | B43: Indirect Labour (m3 / Kg) | C43: =F26M!C43 -> Indirect Labour/Actual Production Volume
...

Sheet F30
A1: LEEDEN NATIONAL OXYGEN LTD | D1: ='F24'!D1:G1 -> AS OF: 11-Oct-2017 | H1: MONTH: | I1: =H4 -> 42979
A2: F30 BALANCE SHEET | D2: CURRENCY: 000s | H2: FX RATE: | I2: 1
D3: Audited | E3: Audited | F3: S$ | G3: S$ | H3: S$ | I3: S$
D4: 42430 | E4: 42795 | F4: 42917 | G4: 42948 | H4: 42979 | I4: =H4 -> 42979
A5: 1 | B5: Cash and Bank Balances | C5: 1000 to 1099Debit, 3000 to 3099Debit
A6: =A5+1 -> 2 | B6: Fixed Deposits | C6: 1100 to 1199
A7: =A6+1 -> 3 | B7: Stocks | C7: 1200 to 1299
A8: =A7+1 -> 4 | B8: Trade Debtors | C8: 1300 to 1399, 1499
A9: =A8+1 -> 5 | B9: Due From Assoc/JV/Related | C9: 1411 to 1433
A10: =A9+1 -> 6 | B10: Due From Interco | C10: 1401 to 1404
A11: =A10+1 -> 7 | B11: Short-Term Investment | C11: 1501 to 1699 Except 1502
A12: =A11+1 -> 8 | B12: Other Debtors/Deposits/Prepayment | C12: 1700, 1800 to 1999
A13: =A12+1 -> 9 | B13: TOTAL CURRENT ASSETS | C13: =SUM(C5:C12)
A14: =A13+1 -> 10 | B14: Freehold Land | C14: 2001 (Exclude A-Z)
A15: =A14+1 -> 11 | B15: Leasehold Properties | C15: 2002 to 2019 (Exclude A-Z)
A16: =A15+1 -> 12 | B16: Construction in Progress | C16: 2021 (Exclude A-Z)
A17: =A16+1 -> 13 | B17: Renovations | C17: 2022 (Exclude A-Z)
... A64: =A63+1 -> 60 | B64: TOTAL LIAB & EQUITY | C64: =C56+C63
B65: Performance Indicators | D65: =D4 -> 42430 | E65: =E4 -> 42795 | F65: =F4 -> 42917 | G65: =G4 -> 42948 | H65: =H4 -> 42979 | I65: =I4 -> 42979
A66: 1 | B66: Debtors Turnover (Days) | C66: (Trade debtors + provision for debts)/ (External sales + External sales other) x No. of days to date
A67: =A66+1 -> 2 | B67: Stocks Turnover (Days) | C67: (Stock + Provision for stock obsolescence)/ -(Total Cost of sales) x No. of days to date
A68: =A67+1 -> 3 | B68: Creditors Turnover (Days) | C68: Account Payable/Cost of Goods Sold x No. of days to date
A69: =A68+1 -> 4 | B69: Liabilities to Equity (Leverage) | C69: Total Liabilities / Total Equity
A70: =A69+1 -> 5 | B70: Debt to Equity | C70: Total Borrowings / Total Equity. Total Borrowings refers to summation of OD or factoring or revolving credit, Trust receipts or ST loans, current portion of Term Loans, Current HP creditors, Long Term Loans and HP Creditors.
A71: =A70+1 -> 6 | B71: Provision for Doubtful Debts | C71: 1301Z
A72: =A71+1 -> 7 | B72: Provision for Stock Obso/Pilferage | C72: 1201Z, 1221Z, 1241Z, 1242Z, 1241L
A73: =A72+1 -> 8 | B73: Provision for Plant Maintenance | C73: 3993

Sheet F30R
A1: LEEDEN NATIONAL OXYGEN LTD | D1: ='F24'!D1:G1 -> AS OF: 11-Oct-2017 | H1: MONTH: | I1: =H4 -> 42979
A2: F30R BALANCE SHEET (RAW) | D2: CURRENCY: | H2: FX RATE: | I2: 1
D3: Audited | E3: Audited | F3: S$ | G3: S$ | H3: S$ | I3: S$
D4: 42430 | E4: 42795 | F4: 42917 | G4: 42948 | H4: 42979 | I4: =H4 -> 42979
A5: 1 | B5: Cash and Bank Balances | C5: ='F30'!C5 -> 1000 to 1099Debit, 3000 to 3099Debit
A6: =A5+1 -> 2 | B6: Fixed Deposits | C6: ='F30'!C6 -> 1100 to 1199
A7: =A6+1 -> 3 | B7: Stocks | C7: ='F30'!C7 -> 1200 to 1299
A8: =A7+1 -> 4 | B8: Trade Debtors | C8: ='F30'!C8 -> 1300 to 1399, 1499
A9: =A8+1 -> 5 | B9: Due From Assoc/JV/Related | C9: ='F30'!C9 -> 1411 to 1433
A10: =A9+1 -> 6 | B10: Due From Interco | C10: ='F30'!C10 -> 1401 to 1404
A11: =A10+1 -> 7 | B11: Short-Term Investment | C11: ='F30'!C11 -> 1501 to 1699 Except 1502
A12: =A11+1 -> 8 | B12: Other Debtors/Deposits/Prepayment | C12: ='F30'!C12 -> 1700, 1800 to 1999
A13: =A12+1 -> 9 | B13: TOTAL CURRENT ASSETS | C13: ='F30'!C13 -> =SUM(C5:C12)
A14: =A13+1 -> 10 | B14: Freehold Land | C14: ='F30'!C14 -> 2001 (Exclude A-Z)
A15: =A14+1 -> 11 | B15: Leasehold Properties | C15: ='F30'!C15 -> 2002 to 2019 (Exclude A-Z)
A16: =A15+1 -> 12 | B16: Construction in Progress | C16: ='F30'!C16 -> 2021 (Exclude A-Z)
A17: =A16+1 -> 13 | B17: Renovations | C17: ='F30'!C17 -> 2022 (Exclude A-Z)
... A64: =A63+1 -> 60 | B64: TOTAL LIAB & EQUITY | C64: ='F30'!C64 -> =C56+C63
B65: Performance Indicators | D65: =D4 -> 42430 | E65: =E4 -> 42795 | F65: =F4 -> 42917 | G65: =G4 -> 42948 | H65: =H4 -> 42979 | I65: =I4 -> 42979
A66: 1 | B66: Debtors Turnover (Days) | C66: ='F30'!C66 -> (Trade debtors + provision for debts)/ (External sales + External sales other) x No. of days to date
A67: =A66+1 -> 2 | B67: Stocks Turnover (Days) | C67: ='F30'!C67 -> (Stock + Provision for stock obsolescence)/ -(Total Cost of sales) x No. of days to date
A68: =A67+1 -> 3 | B68: Creditors Turnover (Days) | C68: ='F30'!C68 -> Account Payable/Cost of Goods Sold x No. of days to date
A69: =A68+1 -> 4 | B69: Liabilities to Equity (Leverage) | C69: ='F30'!C69 -> Total Liabilities / Total Equity
A70: =A69+1 -> 5 | B70: Debt to Equity | C70: ='F30'!C70 -> Total Borrowings / Total Equity. Total Borrowings refers to summation of OD or factoring or revolving credit, Trust receipts or ST loans, current portion of Term Loans, Current HP creditors, Long Term Loans and HP Creditors.
A71: =A70+1 -> 6 | B71: Provision for Doubtful Debts | C71: ='F30'!C71 -> 1301Z
A72: =A71+1 -> 7 | B72: Provision for Stock Obso/Pilferage | C72: ='F30'!C72 -> 1201Z, 1221Z, 1241Z, 1242Z, 1241L
A73: =A72+1 -> 8 | B73: Provision for Plant Maintenance | C73: ='F30'!C73 -> 3993

Sheet F31
A1: LEEDEN NATIONAL OXYGEN LTD | D1: ='F22'!D1:N1 -> AS OF: 11-Oct-2017 | N1: ='F22'!O1 -> FOR THE YEAR OF: 2018
A2: F31 DETAILED P&L ACCOUNT | D2: CURRENCY: S$
D3: 42826 | E3: 42856 | F3: 42887 | G3: 42917 | H3: 42948 | I3: 42979 | J3: 43009 | K3: 43040 | L3: 43070 | M3: 43101 | N3: 43132 | O3: 43160 | P3: Total | Q3: FY 2017 | R3: Variance %
A4: 1 | B4: External Sales–Goods | C4: 5001
A5: =A4+1 -> 2 | B5: External Sales–Project Sales | C5: 5002
A6: =A5+1 -> 3 | B6: External Sales–Cylinder Rental | C6: 5003
A7: =A6+1 -> 4 | B7: External Sales–Equip Rental | C7: 5004
A8: =A7+1 -> 5 | B8: External Sales–Repair & Service | C8: 5005
A9: =A8+1 -> 6 | B9: External Sales–Delivery Charges | C9: 5006
A10: =A9+1 -> 7 | B10: External Sales–Other Charges | C10: 5007
A11: =A10+1 -> 8 | B11: External Sales–Mgmt Fee | C11: 5021
A12: =A11+1 -> 9 | B12: Enternal Sales–Property Rental | C12: 5022
A13: =A12+1 -> 10 | B13: External Sales | C13: =SUM(C4:C12)
