Workbook

Sheet Reference
A1: New
A2: Rename
A3: Remove
A4: New
A5: Combine

Sheet F101 F21 PNL-Debug
A1: DELETE FROM tbFinanceItemSeq where Report = 'PNL'
A3: select s.* , i.ItemName from tbFinanceItemSeq s
A4: LEFT JOIN tbFinanceItem i on s.ItemID = i.ItemID
A5: where s.Report = 'PNL'
A6: order by s.ItemSeqID
A8: Select * from tbFinanceItem where ItemName like '%(PNL)%'
A11: SELECT TOP 10 * FROM tbReport where ReportID = 426;
A12: -- F101 Profit & Loss Account.rpt
A15: Update tbReport
A16: set FileName = 'F101 Profit & Loss Account.rpt' ,
A17: Description = '[COA2016] F21 Profit & Loss Account'
A18: where ReportID = 426;
... A23: where ReportID = 427;

Sheet F101 F21 PNL-Origin
A1: INSERT INTO tbFinanceItemSeq(Report,ItemSeqID,ItemSN,ItemID) VALUES('PNL',1,1,1081)
A2: INSERT INTO tbFinanceItemSeq(Report,ItemSeqID,ItemSN,ItemID) VALUES('PNL',2,2,1082)
A3: INSERT INTO tbFinanceItemSeq(Report,ItemSeqID,ItemSN,ItemID) VALUES('PNL',3,3,1083)
A4: INSERT INTO tbFinanceItemSeq(Report,ItemSeqID,ItemSN,ItemID) VALUES('PNL',4,4,1084)
A5: INSERT INTO tbFinanceItemSeq(Report,ItemSeqID,ItemSN,ItemID) VALUES('PNL',5,5,1085)
A6: INSERT INTO tbFinanceItemSeq(Report,ItemSeqID,ItemSN,ItemID) VALUES('PNL',6,6,1086)
A7: INSERT INTO tbFinanceItemSeq(Report,ItemSeqID,ItemSN,ItemID) VALUES('PNL',7,7,1087)
A8: INSERT INTO tbFinanceItemSeq(Report,ItemSeqID,ItemSN,ItemID) VALUES('PNL',8,8,1088)
A9: INSERT INTO tbFinanceItemSeq(Report,ItemSeqID,ItemSN,ItemID) VALUES('PNL',9,9,1089)
A10: INSERT INTO tbFinanceItemSeq(Report,ItemSeqID,ItemSN,ItemID) VALUES('PNL',10,10,1090)
A11: INSERT INTO tbFinanceItemSeq(Report,ItemSeqID,ItemSN,ItemID) VALUES('PNL',11,11,1091)
A12: INSERT INTO tbFinanceItemSeq(Report,ItemSeqID,ItemSN,ItemID) VALUES('PNL',12,12,1092)
... A65: INSERT INTO tbFinanceItemSeq(Report,ItemSeqID,ItemSN,ItemID) VALUES('PNL',65,9,1140)

Sheet F101 F21 PNL-New
A1: Status | B1: Report | C1: New - ItemSeqID | D1: ItemSeqID | E1: New - ItemSN | F1: ItemSN | G1: ItemID | H1: ItemName | I1: Insert Script
A2: Exist | B2: PNL | C2: =D2 -> 1 | D2: 1 | E2: =F2 -> 1 | F2: 1 | G2: 1081 | H2: (PNL)External Sales | I2: =IF(A2<>"Remove",CONCATENATE("INSERT INTO tbFinanceItemSeq(Report,ItemSeqID,ItemSN,ItemID) VALUES('",B2,"',",C2,",",E2,",",G2,")"),"") -> INSERT INTO tbFinanceItemSeq(Report,ItemSeqID,ItemSN,ItemID) VALUES('PNL',1,1,1081)
A3: Exist | B3: PNL | C3: =D3 -> 2 | D3: 2 | E3: =F3 -> 2 | F3: 2 | G3: 1082 | H3: (PNL)Interco Sales | I3: =IF(A3<>"Remove",CONCATENATE("INSERT INTO tbFinanceItemSeq(Report,ItemSeqID,ItemSN,ItemID) VALUES('",B3,"',",C3,",",E3,",",G3,")"),"") -> INSERT INTO tbFinanceItemSeq(Report,ItemSeqID,ItemSN,ItemID) VALUES('PNL',2,2,1082)
A4: Exist | B4: PNL | C4: =D4 -> 3 | D4: 3 | E4: =F4 -> 3 | F4: 3 | G4: 1083 | H4: (PNL)Total Sales | I4: =IF(A4<>"Remove",CONCATENATE("INSERT INTO tbFinanceItemSeq(Report,ItemSeqID,ItemSN,ItemID) VALUES('",B4,"',",C4,",",E4,",",G4,")"),"") -> INSERT INTO tbFinanceItemSeq(Report,ItemSeqID,ItemSN,ItemID) VALUES('PNL',3,3,1083)
A5: Exist | B5: PNL | C5: =D5 -> 4 | D5: 4 | E5: =F5 -> 4 | F5: 4 | G5: 1084 | H5: (PNL)Cost of External Sales | I5: =IF(A5<>"Remove",CONCATENATE("INSERT INTO tbFinanceItemSeq(Report,ItemSeqID,ItemSN,ItemID) VALUES('",B5,"',",C5,",",E5,",",G5,")"),"") -> INSERT INTO tbFinanceItemSeq(Report,ItemSeqID,ItemSN,ItemID) VALUES('PNL',4,4,1084)
A6: Exist | B6: PNL | C6: =D6 -> 5 | D6: 5 | E6: =F6 -> 5 | F6: 5 | G6: 1085 | H6: (PNL)Cost of Interco Sales | I6: =IF(A6<>"Remove",CONCATENATE("INSERT INTO tbFinanceItemSeq(Report,ItemSeqID,ItemSN,ItemID) VALUES('",B6,"',",C6,",",E6,",",G6,")"),"") -> INSERT INTO tbFinanceItemSeq(Report,ItemSeqID,ItemSN,ItemID) VALUES('PNL',5,5,1085)
A7: Exist | B7: PNL | C7: =D7 -> 6 | D7: 6 | E7: =F7 -> 6 | F7: 6 | G7: 1086 | H7: (PNL)Total Cost of Sales | I7: =IF(A7<>"Remove",CONCATENATE("INSERT INTO tbFinanceItemSeq(Report,ItemSeqID,ItemSN,ItemID) VALUES('",B7,"',",C7,",",E7,",",G7,")"),"") -> INSERT INTO tbFinanceItemSeq(Report,ItemSeqID,ItemSN,ItemID) VALUES('PNL',6,6,1086)
A8: Exist | B8: PNL | C8: =D8 -> 7 | D8: 7 | E8: =F8 -> 7 | F8: 7 | G8: 1087 | H8: (PNL)Gross Profit | I8: =IF(A8<>"Remove",CONCATENATE("INSERT INTO tbFinanceItemSeq(Report,ItemSeqID,ItemSN,ItemID) VALUES('",B8,"',",C8,",",E8,",",G8,")"),"") -> INSERT INTO tbFinanceItemSeq(Report,ItemSeqID,ItemSN,ItemID) VALUES('PNL',7,7,1087)
A9: Exist | B9: PNL | C9: =D9 -> 8 | D9: 8 | E9: =F9 -> 8 | F9: 8 | G9: 1088 | H9: (PNL)Commission Income/Mgt Income | I9: =IF(A9<>"Remove",CONCATENATE("INSERT INTO tbFinanceItemSeq(Report,ItemSeqID,ItemSN,ItemID) VALUES('",B9,"',",C9,",",E9,",",G9,")"),"") -> INSERT INTO tbFinanceItemSeq(Report,ItemSeqID,ItemSN,ItemID) VALUES('PNL',8,8,1088)
A10: New | B10: PNL | C10: 9 | E10: 9 | G10: 1126 | H10: (PNL)Gain/(Loss) Disposal of FA | I10: =IF(A10<>"Remove",CONCATENATE("INSERT INTO tbFinanceItemSeq(Report,ItemSeqID,ItemSN,ItemID) VALUES('",B10,"',",C10,",",E10,",",G10,")"),"") -> INSERT INTO tbFinanceItemSeq(Report,ItemSeqID,ItemSN,ItemID) VALUES('PNL',9,9,1126)
A11: Exist | B11: PNL | C11: =SUM(D11,1) -> 10 | D11: 9 | E11: =SUM(F11,1) -> 10 | F11: 9 | G11: 1089 | H11: (PNL)Other Op Income | I11: =IF(A11<>"Remove",CONCATENATE("INSERT INTO tbFinanceItemSeq(Report,ItemSeqID,ItemSN,ItemID) VALUES('",B11,"',",C11,",",E11,",",G11,")"),"") -> INSERT INTO tbFinanceItemSeq(Report,ItemSeqID,ItemSN,ItemID) VALUES('PNL',10,10,1089)
A12: Exist | B12: PNL | C12: =SUM(D12,1) -> 11 | D12: 10 | E12: =SUM(F12,1) -> 11 | F12: 10 | G12: 1090 | H12: (PNL)Other Op Expense | I12: =IF(A12<>"Remove",CONCATENATE("INSERT INTO tbFinanceItemSeq(Report,ItemSeqID,ItemSN,ItemID) VALUES('",B12,"',",C12,",",E12,",",G12,")"),"") -> INSERT INTO tbFinanceItemSeq(Report,ItemSeqID,ItemSN,ItemID) VALUES('PNL',11,11,1090)
A13: Exist | B13: PNL | C13: =SUM(D13,1) -> 12 | D13: 11 | E13: =SUM(F13,1) -> 12 | F13: 11 | G13: 1091 | H13: (PNL)Total Other Op Income/ (Exp) | I13: =IF(A13<>"Remove",CONCATENATE("INSERT INTO tbFinanceItemSeq(Report,ItemSeqID,ItemSN,ItemID) VALUES('",B13,"',",C13,",",E13,",",G13,")"),"") -> INSERT INTO tbFinanceItemSeq(Report,ItemSeqID,ItemSN,ItemID) VALUES('PNL',12,12,1091)
A14: Exist | B14: PNL | C14: =SUM(D14,1) -> 13 | D14: 12 | E14: =SUM(F14,1) -> 13 | F14: 12 | G14: 1092 | H14: (PNL)S&D Personnel Related Cost | I14: =IF(A14<>"Remove",CONCATENATE("INSERT INTO tbFinanceItemSeq(Report,ItemSeqID,ItemSN,ItemID) VALUES('",B14,"',",C14,",",E14,",",G14,")"),"") -> INSERT INTO tbFinanceItemSeq(Report,ItemSeqID,ItemSN,ItemID) VALUES('PNL',13,13,1092)
A15: Exist | B15: PNL | C15: =SUM(D15,1) -> 14 | D15: 13 | E15: =SUM(F15,1) -> 14 | F15: 13 | G15: 1093 | H15: (PNL)S&D Carriage/Transportation | I15: =IF(A15<>"Remove",CONCATENATE("INSERT INTO tbFinanceItemSeq(Report,ItemSeqID,ItemSN,ItemID) VALUES('",B15,"',",C15,",",E15,",",G15,")"),"") -> INSERT INTO tbFinanceItemSeq(Report,ItemSeqID,ItemSN,ItemID) VALUES('PNL',14,14,1093)
A16: Exist | B16: PNL | C16: =SUM(D16,1) -> 15 | D16: 14 | E16: =SUM(F16,1) -> 15 | F16: 14 | G16: 1094 | H16: (PNL)S&D Advertising/Promotion | I16: =IF(A16<>"Remove",CONCATENATE("INSERT INTO tbFinanceItemSeq(Report,ItemSeqID,ItemSN,ItemID) VALUES('",B16,"',",C16,",",E16,",",G16,")"),"") -> INSERT INTO tbFinanceItemSeq(Report,ItemSeqID,ItemSN,ItemID) VALUES('PNL',15,15,1094)
A17: Exist | B17: PNL | C17: =SUM(D17,1) -> 16 | D17: 15 | E17: =SUM(F17,1) -> 16 | F17: 15 | G17: 1095 | H17: (PNL)S&D Overseas Travelling | I17: =IF(A17<>"Remove",CONCATENATE("INSERT INTO tbFinanceItemSeq(Report,ItemSeqID,ItemSN,ItemID) VALUES('",B17,"',",C17,",",E17,",",G17,")"),"") -> INSERT INTO tbFinanceItemSeq(Report,ItemSeqID,ItemSN,ItemID) VALUES('PNL',16,16,1095)
A18: Exist | B18: PNL | C18: =SUM(D18,1) -> 17 | D18: 16 | E18: =SUM(F18,1) -> 17 | F18: 16 | G18: 1096 | H18: (PNL)S&D Entertainment | I18: =IF(A18<>"Remove",CONCATENATE("INSERT INTO tbFinanceItemSeq(Report,ItemSeqID,ItemSN,ItemID) VALUES('",B18,"',",C18,",",E18,",",G18,")"),"") -> INSERT INTO tbFinanceItemSeq(Report,ItemSeqID,ItemSN,ItemID) VALUES('PNL',17,17,1096)
A19: Exist | B19: PNL | C19: =SUM(D19,1) -> 18 | D19: 17 | E19: =SUM(F19,1) -> 18 | F19: 17 | G19: 1097 | H19: (PNL)S&D Equipment Expenses | I19: =IF(A19<>"Remove",CONCATENATE("INSERT INTO tbFinanceItemSeq(Report,ItemSeqID,ItemSN,ItemID) VALUES('",B19,"',",C19,",",E19,",",G19,")"),"") -> INSERT INTO tbFinanceItemSeq(Report,ItemSeqID,ItemSN,ItemID) VALUES('PNL',18,18,1097)
A20: Exist | B20: PNL | C20: =SUM(D20,1) -> 19 | D20: 18 | E20: =SUM(F20,1) -> 19 | F20: 18 | G20: 1098 | H20: (PNL)S&D Rental/Property Related | I20: =IF(A20<>"Remove",CONCATENATE("INSERT INTO tbFinanceItemSeq(Report,ItemSeqID,ItemSN,ItemID) VALUES('",B20,"',",C20,",",E20,",",G20,")"),"") -> INSERT INTO tbFinanceItemSeq(Report,ItemSeqID,ItemSN,ItemID) VALUES('PNL',19,19,1098)
A21: Exist | B21: PNL | C21: =SUM(D21,1) -> 20 | D21: 19 | E21: =SUM(F21,1) -> 20 | F21: 19 | G21: 1099 | H21: (PNL)S&D Depn of Fixed Assets | I21: =IF(A21<>"Remove",CONCATENATE("INSERT INTO tbFinanceItemSeq(Report,ItemSeqID,ItemSN,ItemID) VALUES('",B21,"',",C21,",",E21,",",G21,")"),"") -> INSERT INTO tbFinanceItemSeq(Report,ItemSeqID,ItemSN,ItemID) VALUES('PNL',20,20,1099)
A22: Exist | B22: PNL | C22: =SUM(D22,1) -> 21 | D22: 20 | E22: =SUM(F22,1) -> 21 | F22: 20 | G22: 1100 | H22: (PNL)S&D Stationery/Printing/Telephone | I22: =IF(A22<>"Remove",CONCATENATE("INSERT INTO tbFinanceItemSeq(Report,ItemSeqID,ItemSN,ItemID) VALUES('",B22,"',",C22,",",E22,",",G22,")"),"") -> INSERT INTO tbFinanceItemSeq(Report,ItemSeqID,ItemSN,ItemID) VALUES('PNL',21,21,1100)
A23: Remove | B23: PNL | D23: 21 | F23: 21 | G23: 1101 | H23: (PNL)Other S&D Expenses | I23: =IF(A23<>"Remove",CONCATENATE("INSERT INTO tbFinanceItemSeq(Report,ItemSeqID,ItemSN,ItemID) VALUES('",B23,"',",C23,",",E23,",",G23,")"),"")
A24: New | B24: PNL | C24: 22 | E24: 22 | G24: 1101 | H24: (PNL)HO/Interco and Other S&D | I24: =IF(A24<>"Remove",CONCATENATE("INSERT INTO tbFinanceItemSeq(Report,ItemSeqID,ItemSN,ItemID) VALUES('",B24,"',",C24,",",E24,",",G24,")"),"") -> INSERT INTO tbFinanceItemSeq(Report,ItemSeqID,ItemSN,ItemID) VALUES('PNL',22,22,1101)
A25: Exist | B25: PNL | C25: =SUM(D25,1) -> 23 | D25: 22 | E25: =SUM(F25,1) -> 23 | F25: 22 | G25: 1102 | H25: (PNL)Total S&D Expenses | I25: =IF(A25<>"Remove",CONCATENATE("INSERT INTO tbFinanceItemSeq(Report,ItemSeqID,ItemSN,ItemID) VALUES('",B25,"',",C25,",",E25,",",G25,")"),"") -> INSERT INTO tbFinanceItemSeq(Report,ItemSeqID,ItemSN,ItemID) VALUES('PNL',23,23,1102)
A26: Exist | B26: PNL | C26: =SUM(D26,1) -> 24 | D26: 23 | E26: =SUM(F26,1) -> 24 | F26: 23 | G26: 1103 | H26: (PNL)A&G Personnel Related Cost | I26: =IF(A26<>"Remove",CONCATENATE("INSERT INTO tbFinanceItemSeq(Report,ItemSeqID,ItemSN,ItemID) VALUES('",B26,"',",C26,",",E26,",",G26,")"),"") -> INSERT INTO tbFinanceItemSeq(Report,ItemSeqID,ItemSN,ItemID) VALUES('PNL',24,24,1103)
A27: Exist | B27: PNL | C27: =SUM(D27,1) -> 25 | D27: 24 | E27: =SUM(F27,1) -> 25 | F27: 24 | G27: 1104 | H27: (PNL)A&G Overseas Travelling | I27: =IF(A27<>"Remove",CONCATENATE("INSERT INTO tbFinanceItemSeq(Report,ItemSeqID,ItemSN,ItemID) VALUES('",B27,"',",C27,",",E27,",",G27,")"),"") -> INSERT INTO tbFinanceItemSeq(Report,ItemSeqID,ItemSN,ItemID) VALUES('PNL',25,25,1104)
A28: Exist | B28: PNL | C28: =SUM(D28,1) -> 26 | D28: 25 | E28: =SUM(F28,1) -> 26 | F28: 25 | G28: 1105 | H28: (PNL)A&G Transportation | I28: =IF(A28<>"Remove",CONCATENATE("INSERT INTO tbFinanceItemSeq(Report,ItemSeqID,ItemSN,ItemID) VALUES('",B28,"',",C28,",",E28,",",G28,")"),"") -> INSERT INTO tbFinanceItemSeq(Report,ItemSeqID,ItemSN,ItemID) VALUES('PNL',26,26,1105)
A29: Remove | B29: PNL | D29: 26 | F29: 26 | G29: 1106 | H29: (PNL)A&G Entertainment | I29: =IF(A29<>"Remove",CONCATENATE("INSERT INTO tbFinanceItemSeq(Report,ItemSeqID,ItemSN,ItemID) VALUES('",B29,"',",C29,",",E29,",",G29,")"),"")
A30: New | B30: PNL | C30: 27 | E30: 27 | G30: 1106 | H30: (PNL)A&G Entertainment & Donation | I30: =IF(A30<>"Remove",CONCATENATE("INSERT INTO tbFinanceItemSeq(Report,ItemSeqID,ItemSN,ItemID) VALUES('",B30,"',",C30,",",E30,",",G30,")"),"") -> INSERT INTO tbFinanceItemSeq(Report,ItemSeqID,ItemSN,ItemID) VALUES('PNL',27,27,1106)
A31: Exist | B31: PNL | C31: =SUM(D31,1) -> 28 | D31: 27 | E31: =SUM(F31,1) -> 28 | F31: 27 | G31: 1107 | H31: (PNL)A&G Equipment Expenses | I31: =IF(A31<>"Remove",CONCATENATE("INSERT INTO tbFinanceItemSeq(Report,ItemSeqID,ItemSN,ItemID) VALUES('",B31,"',",C31,",",E31,",",G31,")"),"") -> INSERT INTO tbFinanceItemSeq(Report,ItemSeqID,ItemSN,ItemID) VALUES('PNL',28,28,1107)
A32: Exist | B32: PNL | C32: =SUM(D32,1) -> 29 | D32: 28 | E32: =SUM(F32,1) -> 29 | F32: 28 | G32: 1108 | H32: (PNL)A&G Rental/Property Related | I32: =IF(A32<>"Remove",CONCATENATE("INSERT INTO tbFinanceItemSeq(Report,ItemSeqID,ItemSN,ItemID) VALUES('",B32,"',",C32,",",E32,",",G32,")"),"") -> INSERT INTO tbFinanceItemSeq(Report,ItemSeqID,ItemSN,ItemID) VALUES('PNL',29,29,1108)
A33: Exist | B33: PNL | C33: =SUM(D33,1) -> 30 | D33: 29 | E33: =SUM(F33,1) -> 30 | F33: 29 | G33: 1109 | H33: (PNL)A&G Depn of Fixed Assets | I33: =IF(A33<>"Remove",CONCATENATE("INSERT INTO tbFinanceItemSeq(Report,ItemSeqID,ItemSN,ItemID) VALUES('",B33,"',",C33,",",E33,",",G33,")"),"") -> INSERT INTO tbFinanceItemSeq(Report,ItemSeqID,ItemSN,ItemID) VALUES('PNL',30,30,1109)
A34: Exist | B34: PNL | C34: =SUM(D34,1) -> 31 | D34: 30 | E34: =SUM(F34,1) -> 31 | F34: 30 | G34: 1110 | H34: (PNL)A&G Stationery/Printing/Telephone | I34: =IF(A34<>"Remove",CONCATENATE("INSERT INTO tbFinanceItemSeq(Report,ItemSeqID,ItemSN,ItemID) VALUES('",B34,"',",C34,",",E34,",",G34,")"),"") -> INSERT INTO tbFinanceItemSeq(Report,ItemSeqID,ItemSN,ItemID) VALUES('PNL',31,31,1110)
A35: Exist | B35: PNL | C35: =SUM(D35,1) -> 32 | D35: 31 | E35: =SUM(F35,1) -> 32 | F35: 31 | G35: 1111 | H35: (PNL)A&G Legal/Prof Fees/Ins/Safety | I35: =IF(A35<>"Remove",CONCATENATE("INSERT INTO tbFinanceItemSeq(Report,ItemSeqID,ItemSN,ItemID) VALUES('",B35,"',",C35,",",E35,",",G35,")"),"") -> INSERT INTO tbFinanceItemSeq(Report,ItemSeqID,ItemSN,ItemID) VALUES('PNL',32,32,1111)
A36: Exist | B36: PNL | C36: =SUM(D36,1) -> 33 | D36: 32 | E36: =SUM(F36,1) -> 33 | F36: 32 | G36: 1376 | H36: (PNL)A&G IT System Exps | I36: =IF(A36<>"Remove",CONCATENATE("INSERT INTO tbFinanceItemSeq(Report,ItemSeqID,ItemSN,ItemID) VALUES('",B36,"',",C36,",",E36,",",G36,")"),"") -> INSERT INTO tbFinanceItemSeq(Report,ItemSeqID,ItemSN,ItemID) VALUES('PNL',33,33,1376)
A37: Exist | B37: PNL | C37: =SUM(D37,1) -> 34 | D37: 33 | E37: =SUM(F37,1) -> 34 | F37: 33 | G37: 1377 | H37: (PNL)A&G Purchasing Exps | I37: =IF(A37<>"Remove",CONCATENATE("INSERT INTO tbFinanceItemSeq(Report,ItemSeqID,ItemSN,ItemID) VALUES('",B37,"',",C37,",",E37,",",G37,")"),"") -> INSERT INTO tbFinanceItemSeq(Report,ItemSeqID,ItemSN,ItemID) VALUES('PNL',34,34,1377)
A38: Exist | B38: PNL | C38: =SUM(D38,1) -> 35 | D38: 34 | E38: =SUM(F38,1) -> 35 | F38: 34 | G38: 1112 | H38: (PNL)A&G Direct Expenses | I38: =IF(A38<>"Remove",CONCATENATE("INSERT INTO tbFinanceItemSeq(Report,ItemSeqID,ItemSN,ItemID) VALUES('",B38,"',",C38,",",E38,",",G38,")"),"") -> INSERT INTO tbFinanceItemSeq(Report,ItemSeqID,ItemSN,ItemID) VALUES('PNL',35,35,1112)
A39: Exist | B39: PNL | C39: =SUM(D39,1) -> 36 | D39: 35 | E39: =SUM(F39,1) -> 36 | F39: 35 | G39: 1113 | H39: (PNL)Prov for Stock Obso/Pilferage | I39: =IF(A39<>"Remove",CONCATENATE("INSERT INTO tbFinanceItemSeq(Report,ItemSeqID,ItemSN,ItemID) VALUES('",B39,"',",C39,",",E39,",",G39,")"),"") -> INSERT INTO tbFinanceItemSeq(Report,ItemSeqID,ItemSN,ItemID) VALUES('PNL',36,36,1113)
A40: Exist | B40: PNL | C40: =SUM(D40,1) -> 37 | D40: 36 | E40: =SUM(F40,1) -> 37 | F40: 36 | G40: 1114 | H40: (PNL)Prov for Doubtful Debts | I40: =IF(A40<>"Remove",CONCATENATE("INSERT INTO tbFinanceItemSeq(Report,ItemSeqID,ItemSN,ItemID) VALUES('",B40,"',",C40,",",E40,",",G40,")"),"") -> INSERT INTO tbFinanceItemSeq(Report,ItemSeqID,ItemSN,ItemID) VALUES('PNL',37,37,1114)
...

Sheet F21R PNLR-Script
A1: INSERT INTO
A2: tbReport
A3: (ReportCategoryID,Description,FileName,StoredProcName,CreatedBy,CreatedDate,ModifiedBy,ModifiedDate,IsActive,IsExternalReport)
A4: VALUES
A5: (1,'[COA2016] F21R Profit & loss Account (Raw)','F21R Profit & Loss Account (Raw).rpt',null,1,CURRENT_TIMESTAMP,Null,Null,1,0);

Sheet F21R PNLR-New
A1: Status | B1: Report | C1: New ItemSeqID | D1: New ItemSNNO | E1: ItemID | F1: PNL Item Name | G1: PNLR - Item Name | H1: Insert Script
A2: ='F101 F21 PNL-New'!A2 -> Exist | B2: PNLR | C2: ='F101 F21 PNL-New'!C2 -> 1 | D2: ='F101 F21 PNL-New'!E2 -> 1 | E2: =CONCATENATE("(SELECT ItemID FROM tbFinanceItem where ItemName = '",G2,"')") -> (SELECT ItemID FROM tbFinanceItem where ItemName = '(PNLR)External Sales') | F2: ='F101 F21 PNL-New'!H2 -> (PNL)External Sales | G2: =REPLACE(F2,2,3,B2) -> (PNLR)External Sales | H2: =IF(A2<>"Remove",CONCATENATE("INSERT INTO tbFinanceItemSeq(Report,ItemSeqID,ItemSN,ItemID) VALUES('",B2,"',",C2,",",D2,",",E2,")"),"") -> INSERT INTO tbFinanceItemSeq(Report,ItemSeqID,ItemSN,ItemID) VALUES('PNLR',1,1,(SELECT ItemID FROM tbFinanceItem where ItemName = '(PNLR)External Sales'))
A3: ='F101 F21 PNL-New'!A3 -> Exist | B3: PNLR | C3: ='F101 F21 PNL-New'!C3 -> 2 | D3: ='F101 F21 PNL-New'!E3 -> 2 | E3: =CONCATENATE("(SELECT ItemID FROM tbFinanceItem where ItemName = '",G3,"')") -> (SELECT ItemID FROM tbFinanceItem where ItemName = '(PNLR)Interco Sales') | F3: ='F101 F21 PNL-New'!H3 -> (PNL)Interco Sales | G3: =REPLACE(F3,2,3,B3) -> (PNLR)Interco Sales | H3: =IF(A3<>"Remove",CONCATENATE("INSERT INTO tbFinanceItemSeq(Report,ItemSeqID,ItemSN,ItemID) VALUES('",B3,"',",C3,",",D3,",",E3,")"),"") -> INSERT INTO tbFinanceItemSeq(Report,ItemSeqID,ItemSN,ItemID) VALUES('PNLR',2,2,(SELECT ItemID FROM tbFinanceItem where ItemName = '(PNLR)Interco Sales'))
A4: ='F101 F21 PNL-New'!A4 -> Exist | B4: PNLR | C4: ='F101 F21 PNL-New'!C4 -> 3 | D4: ='F101 F21 PNL-New'!E4 -> 3 | E4: =CONCATENATE("(SELECT ItemID FROM tbFinanceItem where ItemName = '",G4,"')") -> (SELECT ItemID FROM tbFinanceItem where ItemName = '(PNLR)Total Sales') | F4: ='F101 F21 PNL-New'!H4 -> (PNL)Total Sales | G4: =REPLACE(F4,2,3,B4) -> (PNLR)Total Sales | H4: =IF(A4<>"Remove",CONCATENATE("INSERT INTO tbFinanceItemSeq(Report,ItemSeqID,ItemSN,ItemID) VALUES('",B4,"',",C4,",",D4,",",E4,")"),"") -> INSERT INTO tbFinanceItemSeq(Report,ItemSeqID,ItemSN,ItemID) VALUES('PNLR',3,3,(SELECT ItemID FROM tbFinanceItem where ItemName = '(PNLR)Total Sales'))
A5: ='F101 F21 PNL-New'!A5 -> Exist | B5: PNLR | C5: ='F101 F21 PNL-New'!C5 -> 4 | D5: ='F101 F21 PNL-New'!E5 -> 4 | E5: =CONCATENATE("(SELECT ItemID FROM tbFinanceItem where ItemName = '",G5,"')") -> (SELECT ItemID FROM tbFinanceItem where ItemName = '(PNLR)Cost of External Sales') | F5: ='F101 F21 PNL-New'!H5 -> (PNL)Cost of External Sales | G5: =REPLACE(F5,2,3,B5) -> (PNLR)Cost of External Sales | H5: =IF(A5<>"Remove",CONCATENATE("INSERT INTO tbFinanceItemSeq(Report,ItemSeqID,ItemSN,ItemID) VALUES('",B5,"',",C5,",",D5,",",E5,")"),"") -> INSERT INTO tbFinanceItemSeq(Report,ItemSeqID,ItemSN,ItemID) VALUES('PNLR',4,4,(SELECT ItemID FROM tbFinanceItem where ItemName = '(PNLR)Cost of External Sales'))
A6: ='F101 F21 PNL-New'!A6 -> Exist | B6: PNLR | C6: ='F101 F21 PNL-New'!C6 -> 5 | D6: ='F101 F21 PNL-New'!E6 -> 5 | E6: =CONCATENATE("(SELECT ItemID FROM tbFinanceItem where ItemName = '",G6,"')") -> (SELECT ItemID FROM tbFinanceItem where ItemName = '(PNLR)Cost of Interco Sales') | F6: ='F101 F21 PNL-New'!H6 -> (PNL)Cost of Interco Sales | G6: =REPLACE(F6,2,3,B6) -> (PNLR)Cost of Interco Sales | H6: =IF(A6<>"Remove",CONCATENATE("INSERT INTO tbFinanceItemSeq(Report,ItemSeqID,ItemSN,ItemID) VALUES('",B6,"',",C6,",",D6,",",E6,")"),"") -> INSERT INTO tbFinanceItemSeq(Report,ItemSeqID,ItemSN,ItemID) VALUES('PNLR',5,5,(SELECT ItemID FROM tbFinanceItem where ItemName = '(PNLR)Cost of Interco Sales'))
A7: ='F101 F21 PNL-New'!A7 -> Exist | B7: PNLR | C7: ='F101 F21 PNL-New'!C7 -> 6 | D7: ='F101 F21 PNL-New'!E7 -> 6 | E7: =CONCATENATE("(SELECT ItemID FROM tbFinanceItem where ItemName = '",G7,"')") -> (SELECT ItemID FROM tbFinanceItem where ItemName = '(PNLR)Total Cost of Sales') | F7: ='F101 F21 PNL-New'!H7 -> (PNL)Total Cost of Sales | G7: =REPLACE(F7,2,3,B7) -> (PNLR)Total Cost of Sales | H7: =IF(A7<>"Remove",CONCATENATE("INSERT INTO tbFinanceItemSeq(Report,ItemSeqID,ItemSN,ItemID) VALUES('",B7,"',",C7,",",D7,",",E7,")"),"") -> INSERT INTO tbFinanceItemSeq(Report,ItemSeqID,ItemSN,ItemID) VALUES('PNLR',6,6,(SELECT ItemID FROM tbFinanceItem where ItemName = '(PNLR)Total Cost of Sales'))
A8: ='F101 F21 PNL-New'!A8 -> Exist | B8: PNLR | C8: ='F101 F21 PNL-New'!C8 -> 7 | D8: ='F101 F21 PNL-New'!E8 -> 7 | E8: =CONCATENATE("(SELECT ItemID FROM tbFinanceItem where ItemName = '",G8,"')") -> (SELECT ItemID FROM tbFinanceItem where ItemName = '(PNLR)Gross Profit') | F8: ='F101 F21 PNL-New'!H8 -> (PNL)Gross Profit | G8: =REPLACE(F8,2,3,B8) -> (PNLR)Gross Profit | H8: =IF(A8<>"Remove",CONCATENATE("INSERT INTO tbFinanceItemSeq(Report,ItemSeqID,ItemSN,ItemID) VALUES('",B8,"',",C8,",",D8,",",E8,")"),"") -> INSERT INTO tbFinanceItemSeq(Report,ItemSeqID,ItemSN,ItemID) VALUES('PNLR',7,7,(SELECT ItemID FROM tbFinanceItem where ItemName = '(PNLR)Gross Profit'))
A9: ='F101 F21 PNL-New'!A9 -> Exist | B9: PNLR | C9: ='F101 F21 PNL-New'!C9 -> 8 | D9: ='F101 F21 PNL-New'!E9 -> 8 | E9: =CONCATENATE("(SELECT ItemID FROM tbFinanceItem where ItemName = '",G9,"')") -> (SELECT ItemID FROM tbFinanceItem where ItemName = '(PNLR)Commission Income/Mgt Income') | F9: ='F101 F21 PNL-New'!H9 -> (PNL)Commission Income/Mgt Income | G9: =REPLACE(F9,2,3,B9) -> (PNLR)Commission Income/Mgt Income | H9: =IF(A9<>"Remove",CONCATENATE("INSERT INTO tbFinanceItemSeq(Report,ItemSeqID,ItemSN,ItemID) VALUES('",B9,"',",C9,",",D9,",",E9,")"),"") -> INSERT INTO tbFinanceItemSeq(Report,ItemSeqID,ItemSN,ItemID) VALUES('PNLR',8,8,(SELECT ItemID FROM tbFinanceItem where ItemName = '(PNLR)Commission Income/Mgt Income'))
A10: ='F101 F21 PNL-New'!A10 -> New | B10: PNLR | C10: ='F101 F21 PNL-New'!C10 -> 9 | D10: ='F101 F21 PNL-New'!E10 -> 9 | E10: =CONCATENATE("(SELECT ItemID FROM tbFinanceItem where ItemName = '",G10,"')") -> (SELECT ItemID FROM tbFinanceItem where ItemName = '(PNLR)Gain/(Loss) Disposal of FA') | F10: ='F101 F21 PNL-New'!H10 -> (PNL)Gain/(Loss) Disposal of FA | G10: =REPLACE(F10,2,3,B10) -> (PNLR)Gain/(Loss) Disposal of FA | H10: =IF(A10<>"Remove",CONCATENATE("INSERT INTO tbFinanceItemSeq(Report,ItemSeqID,ItemSN,ItemID) VALUES('",B10,"',",C10,",",D10,",",E10,")"),"") -> INSERT INTO tbFinanceItemSeq(Report,ItemSeqID,ItemSN,ItemID) VALUES('PNLR',9,9,(SELECT ItemID FROM tbFinanceItem where ItemName = '(PNLR)Gain/(Loss) Disposal of FA'))
A11: ='F101 F21 PNL-New'!A11 -> Exist | B11: PNLR | C11: ='F101 F21 PNL-New'!C11 -> 10 | D11: ='F101 F21 PNL-New'!E11 -> 10 | E11: =CONCATENATE("(SELECT ItemID FROM tbFinanceItem where ItemName = '",G11,"')") -> (SELECT ItemID FROM tbFinanceItem where ItemName = '(PNLR)Other Op Income') | F11: ='F101 F21 PNL-New'!H11 -> (PNL)Other Op Income | G11: =REPLACE(F11,2,3,B11) -> (PNLR)Other Op Income | H11: =IF(A11<>"Remove",CONCATENATE("INSERT INTO tbFinanceItemSeq(Report,ItemSeqID,ItemSN,ItemID) VALUES('",B11,"',",C11,",",D11,",",E11,")"),"") -> INSERT INTO tbFinanceItemSeq(Report,ItemSeqID,ItemSN,ItemID) VALUES('PNLR',10,10,(SELECT ItemID FROM tbFinanceItem where ItemName = '(PNLR)Other Op Income'))
A12: ='F101 F21 PNL-New'!A12 -> Exist | B12: PNLR | C12: ='F101 F21 PNL-New'!C12 -> 11 | D12: ='F101 F21 PNL-New'!E12 -> 11 | E12: =CONCATENATE("(SELECT ItemID FROM tbFinanceItem where ItemName = '",G12,"')") -> (SELECT ItemID FROM tbFinanceItem where ItemName = '(PNLR)Other Op Expense') | F12: ='F101 F21 PNL-New'!H12 -> (PNL)Other Op Expense | G12: =REPLACE(F12,2,3,B12) -> (PNLR)Other Op Expense | H12: =IF(A12<>"Remove",CONCATENATE("INSERT INTO tbFinanceItemSeq(Report,ItemSeqID,ItemSN,ItemID) VALUES('",B12,"',",C12,",",D12,",",E12,")"),"") -> INSERT INTO tbFinanceItemSeq(Report,ItemSeqID,ItemSN,ItemID) VALUES('PNLR',11,11,(SELECT ItemID FROM tbFinanceItem where ItemName = '(PNLR)Other Op Expense'))
A13: ='F101 F21 PNL-New'!A13 -> Exist | B13: PNLR | C13: ='F101 F21 PNL-New'!C13 -> 12 | D13: ='F101 F21 PNL-New'!E13 -> 12 | E13: =CONCATENATE("(SELECT ItemID FROM tbFinanceItem where ItemName = '",G13,"')") -> (SELECT ItemID FROM tbFinanceItem where ItemName = '(PNLR)Total Other Op Income/ (Exp)') | F13: ='F101 F21 PNL-New'!H13 -> (PNL)Total Other Op Income/ (Exp) | G13: =REPLACE(F13,2,3,B13) -> (PNLR)Total Other Op Income/ (Exp) | H13: =IF(A13<>"Remove",CONCATENATE("INSERT INTO tbFinanceItemSeq(Report,ItemSeqID,ItemSN,ItemID) VALUES('",B13,"',",C13,",",D13,",",E13,")"),"") -> INSERT INTO tbFinanceItemSeq(Report,ItemSeqID,ItemSN,ItemID) VALUES('PNLR',12,12,(SELECT ItemID FROM tbFinanceItem where ItemName = '(PNLR)Total Other Op Income/ (Exp)'))
... A73: ='F101 F21 PNL-New'!A73 -> Exist | B73: PNLR | C73: ='F101 F21 PNL-New'!C73 -> 64 | D73: ='F101 F21 PNL-New'!E73 -> 8 | E73: =CONCATENATE("(SELECT ItemID FROM tbFinanceItem where ItemName = '",G73,"')") -> (SELECT ItemID FROM tbFinanceItem where ItemName = 'PPNLRit After Taxation %') | F73: ='F101 F21 PNL-New'!H73 -> Profit After Taxation % | G73: =REPLACE(F73,2,3,B73) -> PPNLRit After Taxation % | H73: =IF(A73<>"Remove",CONCATENATE("INSERT INTO tbFinanceItemSeq(Report,ItemSeqID,ItemSN,ItemID) VALUES('",B73,"',",C73,",",D73,",",E73,")"),"") -> INSERT INTO tbFinanceItemSeq(Report,ItemSeqID,ItemSN,ItemID) VALUES('PNLR',64,8,(SELECT ItemID FROM tbFinanceItem where ItemName = 'PPNLRit After Taxation %'))

Sheet F102 F22 PNLS-Debug
A1: DELETE FROM tbFinanceItemSeq where Report = 'PNLS'
A3: SELECT TOP 10 * FROM tbReport where ReportID = 428;
A4: F102 Profit & Loss Account By Month.rpt
A5: procReportFinancePNLByMonth
A8: select s.* , i.ItemName from tbFinanceItemSeq s
A9: LEFT JOIN tbFinanceItem i on s.ItemID = i.ItemID
A10: where s.Report = 'PNLS'
A11: order by s.ItemSeqID
A13: SELECT TOP 10 * FROM tbReport where ReportID = 426;
A14: -- F101S Profit & Loss Account.rpt
A18: Update tbReport
A19: set FileName = 'F102 Profit & Loss Account By Month.rpt' ,
... A21: where ReportID = 428;

Sheet F102 F22 PNLS-Origin
A1: Report | B1: ItemSeqID | C1: ItemSN | D1: ItemID | E1: ItemName | F1: Insert Script
A2: PNLS | B2: 1 | C2: 1 | D2: 1081 | E2: (PNL)External Sales | F2: =CONCATENATE("INSERT INTO tbFinanceItemSeq(Report,ItemSeqID,ItemSN,ItemID) VALUES('",A2,"',",B2,",",C2,",",D2,")") -> INSERT INTO tbFinanceItemSeq(Report,ItemSeqID,ItemSN,ItemID) VALUES('PNLS',1,1,1081)
A3: PNLS | B3: 2 | C3: 2 | D3: 1082 | E3: (PNL)Interco Sales | F3: =CONCATENATE("INSERT INTO tbFinanceItemSeq(Report,ItemSeqID,ItemSN,ItemID) VALUES('",A3,"',",B3,",",C3,",",D3,")") -> INSERT INTO tbFinanceItemSeq(Report,ItemSeqID,ItemSN,ItemID) VALUES('PNLS',2,2,1082)
A4: PNLS | B4: 3 | C4: 3 | D4: 1083 | E4: (PNL)Total Sales | F4: =CONCATENATE("INSERT INTO tbFinanceItemSeq(Report,ItemSeqID,ItemSN,ItemID) VALUES('",A4,"',",B4,",",C4,",",D4,")") -> INSERT INTO tbFinanceItemSeq(Report,ItemSeqID,ItemSN,ItemID) VALUES('PNLS',3,3,1083)
A5: PNLS | B5: 4 | C5: 4 | D5: 1084 | E5: (PNL)Cost of External Sales | F5: =CONCATENATE("INSERT INTO tbFinanceItemSeq(Report,ItemSeqID,ItemSN,ItemID) VALUES('",A5,"',",B5,",",C5,",",D5,")") -> INSERT INTO tbFinanceItemSeq(Report,ItemSeqID,ItemSN,ItemID) VALUES('PNLS',4,4,1084)
A6: PNLS | B6: 5 | C6: 5 | D6: 1085 | E6: (PNL)Cost of Interco Sales | F6: =CONCATENATE("INSERT INTO tbFinanceItemSeq(Report,ItemSeqID,ItemSN,ItemID) VALUES('",A6,"',",B6,",",C6,",",D6,")") -> INSERT INTO tbFinanceItemSeq(Report,ItemSeqID,ItemSN,ItemID) VALUES('PNLS',5,5,1085)
A7: PNLS | B7: 6 | C7: 6 | D7: 1086 | E7: (PNL)Total Cost of Sales | F7: =CONCATENATE("INSERT INTO tbFinanceItemSeq(Report,ItemSeqID,ItemSN,ItemID) VALUES('",A7,"',",B7,",",C7,",",D7,")") -> INSERT INTO tbFinanceItemSeq(Report,ItemSeqID,ItemSN,ItemID) VALUES('PNLS',6,6,1086)
A8: PNLS | B8: 7 | C8: 7 | D8: 1087 | E8: (PNL)Gross Profit | F8: =CONCATENATE("INSERT INTO tbFinanceItemSeq(Report,ItemSeqID,ItemSN,ItemID) VALUES('",A8,"',",B8,",",C8,",",D8,")") -> INSERT INTO tbFinanceItemSeq(Report,ItemSeqID,ItemSN,ItemID) VALUES('PNLS',7,7,1087)
A9: PNLS | B9: 8 | C9: 8 | D9: 1088 | E9: (PNL)Commission Income/Mgt Income | F9: =CONCATENATE("INSERT INTO tbFinanceItemSeq(Report,ItemSeqID,ItemSN,ItemID) VALUES('",A9,"',",B9,",",C9,",",D9,")") -> INSERT INTO tbFinanceItemSeq(Report,ItemSeqID,ItemSN,ItemID) VALUES('PNLS',8,8,1088)
A10: PNLS | B10: 9 | C10: 9 | D10: 1089 | E10: (PNL)Other Op Income | F10: =CONCATENATE("INSERT INTO tbFinanceItemSeq(Report,ItemSeqID,ItemSN,ItemID) VALUES('",A10,"',",B10,",",C10,",",D10,")") -> INSERT INTO tbFinanceItemSeq(Report,ItemSeqID,ItemSN,ItemID) VALUES('PNLS',9,9,1089)
A11: PNLS | B11: 10 | C11: 10 | D11: 1090 | E11: (PNL)Other Op Expense | F11: =CONCATENATE("INSERT INTO tbFinanceItemSeq(Report,ItemSeqID,ItemSN,ItemID) VALUES('",A11,"',",B11,",",C11,",",D11,")") -> INSERT INTO tbFinanceItemSeq(Report,ItemSeqID,ItemSN,ItemID) VALUES('PNLS',10,10,1090)
A12: PNLS | B12: 11 | C12: 11 | D12: 1091 | E12: (PNL)Total Other Op Income/ (Exp) | F12: =CONCATENATE("INSERT INTO tbFinanceItemSeq(Report,ItemSeqID,ItemSN,ItemID) VALUES('",A12,"',",B12,",",C12,",",D12,")") -> INSERT INTO tbFinanceItemSeq(Report,ItemSeqID,ItemSN,ItemID) VALUES('PNLS',11,11,1091)
A13: PNLS | B13: 12 | C13: 12 | D13: 1102 | E13: (PNL)Total S&D Expenses | F13: =CONCATENATE("INSERT INTO tbFinanceItemSeq(Report,ItemSeqID,ItemSN,ItemID) VALUES('",A13,"',",B13,",",C13,",",D13,")") -> INSERT INTO tbFinanceItemSeq(Report,ItemSeqID,ItemSN,ItemID) VALUES('PNLS',12,12,1102)
... A30: PNLS | B30: 29 | C30: 1 | D30: 1135 | E30: Gross Profits Margin % | F30: =CONCATENATE("INSERT INTO tbFinanceItemSeq(Report,ItemSeqID,ItemSN,ItemID) VALUES('",A30,"',",B30,",",C30,",",D30,")") -> INSERT INTO tbFinanceItemSeq(Report,ItemSeqID,ItemSN,ItemID) VALUES('PNLS',29,1,1135)
A31: PNLS | B31: 30 | C31: 2 | D31: 1136 | E31: =- External Sales GP % -> #NAME? | F31: =CONCATENATE("INSERT INTO tbFinanceItemSeq(Report,ItemSeqID,ItemSN,ItemID) VALUES('",A31,"',",B31,",",C31,",",D31,")") -> INSERT INTO tbFinanceItemSeq(Report,ItemSeqID,ItemSN,ItemID) VALUES('PNLS',30,2,1136)
A32: PNLS | B32: 31 | C32: 3 | D32: 1137 | E32: =- Interco Sales GP % -> #NAME? | F32: =CONCATENATE("INSERT INTO tbFinanceItemSeq(Report,ItemSeqID,ItemSN,ItemID) VALUES('",A32,"',",B32,",",C32,",",D32,")") -> INSERT INTO tbFinanceItemSeq(Report,ItemSeqID,ItemSN,ItemID) VALUES('PNLS',31,3,1137)
A33: PNLS | B33: 32 | C33: 4 | D33: 50 | E33: Selling & Dist Margin % | F33: =CONCATENATE("INSERT INTO tbFinanceItemSeq(Report,ItemSeqID,ItemSN,ItemID) VALUES('",A33,"',",B33,",",C33,",",D33,")") -> INSERT INTO tbFinanceItemSeq(Report,ItemSeqID,ItemSN,ItemID) VALUES('PNLS',32,4,50)
A34: PNLS | B34: 33 | C34: 5 | D34: 1138 | E34: A&G Margin Direct % | F34: =CONCATENATE("INSERT INTO tbFinanceItemSeq(Report,ItemSeqID,ItemSN,ItemID) VALUES('",A34,"',",B34,",",C34,",",D34,")") -> INSERT INTO tbFinanceItemSeq(Report,ItemSeqID,ItemSN,ItemID) VALUES('PNLS',33,5,1138)
A35: PNLS | B35: 34 | C35: 6 | D35: 1139 | E35: A&G Margin Total % | F35: =CONCATENATE("INSERT INTO tbFinanceItemSeq(Report,ItemSeqID,ItemSN,ItemID) VALUES('",A35,"',",B35,",",C35,",",D35,")") -> INSERT INTO tbFinanceItemSeq(Report,ItemSeqID,ItemSN,ItemID) VALUES('PNLS',34,6,1139)
A36: PNLS | B36: 35 | C36: 7 | D36: 53 | E36: Operating Profit Margin % | F36: =CONCATENATE("INSERT INTO tbFinanceItemSeq(Report,ItemSeqID,ItemSN,ItemID) VALUES('",A36,"',",B36,",",C36,",",D36,")") -> INSERT INTO tbFinanceItemSeq(Report,ItemSeqID,ItemSN,ItemID) VALUES('PNLS',35,7,53)
A37: PNLS | B37: 36 | C37: 8 | D37: 52 | E37: Profit Before Taxation % | F37: =CONCATENATE("INSERT INTO tbFinanceItemSeq(Report,ItemSeqID,ItemSN,ItemID) VALUES('",A37,"',",B37,",",C37,",",D37,")") -> INSERT INTO tbFinanceItemSeq(Report,ItemSeqID,ItemSN,ItemID) VALUES('PNLS',36,8,52)
A38: PNLS | B38: 37 | C38: 9 | D38: 1140 | E38: Profit After Taxation % | F38: =CONCATENATE("INSERT INTO tbFinanceItemSeq(Report,ItemSeqID,ItemSN,ItemID) VALUES('",A38,"',",B38,",",C38,",",D38,")") -> INSERT INTO tbFinanceItemSeq(Report,ItemSeqID,ItemSN,ItemID) VALUES('PNLS',37,9,1140)

Sheet F102 F22 PNLS-NEW
A1: Status | B1: Report | C1: New - ItemSeqID | D1: ItemSeqID | E1: New - ItemSN | F1: ItemSN | G1: ItemID | H1: ItemName | I1: Insert Script
A2: Exist | B2: PNLS | C2: =D2 -> 1 | D2: 1 | E2: =F2 -> 1 | F2: 1 | G2: 1081 | H2: (PNL)External Sales | I2: =IF(A2<>"Remove",CONCATENATE("INSERT INTO tbFinanceItemSeq(Report,ItemSeqID,ItemSN,ItemID) VALUES('",B2,"',",C2,",",E2,",",G2,")"),"") -> INSERT INTO tbFinanceItemSeq(Report,ItemSeqID,ItemSN,ItemID) VALUES('PNLS',1,1,1081)
A3: Exist | B3: PNLS | C3: =D3 -> 2 | D3: 2 | E3: =F3 -> 2 | F3: 2 | G3: 1082 | H3: (PNL)Interco Sales | I3: =IF(A3<>"Remove",CONCATENATE("INSERT INTO tbFinanceItemSeq(Report,ItemSeqID,ItemSN,ItemID) VALUES('",B3,"',",C3,",",E3,",",G3,")"),"") -> INSERT INTO tbFinanceItemSeq(Report,ItemSeqID,ItemSN,ItemID) VALUES('PNLS',2,2,1082)
A4: Exist | B4: PNLS | C4: =D4 -> 3 | D4: 3 | E4: =F4 -> 3 | F4: 3 | G4: 1083 | H4: (PNL)Total Sales | I4: =IF(A4<>"Remove",CONCATENATE("INSERT INTO tbFinanceItemSeq(Report,ItemSeqID,ItemSN,ItemID) VALUES('",B4,"',",C4,",",E4,",",G4,")"),"") -> INSERT INTO tbFinanceItemSeq(Report,ItemSeqID,ItemSN,ItemID) VALUES('PNLS',3,3,1083)
A5: Exist | B5: PNLS | C5: =D5 -> 4 | D5: 4 | E5: =F5 -> 4 | F5: 4 | G5: 1084 | H5: (PNL)Cost of External Sales | I5: =IF(A5<>"Remove",CONCATENATE("INSERT INTO tbFinanceItemSeq(Report,ItemSeqID,ItemSN,ItemID) VALUES('",B5,"',",C5,",",E5,",",G5,")"),"") -> INSERT INTO tbFinanceItemSeq(Report,ItemSeqID,ItemSN,ItemID) VALUES('PNLS',4,4,1084)
A6: Exist | B6: PNLS | C6: =D6 -> 5 | D6: 5 | E6: =F6 -> 5 | F6: 5 | G6: 1085 | H6: (PNL)Cost of Interco Sales | I6: =IF(A6<>"Remove",CONCATENATE("INSERT INTO tbFinanceItemSeq(Report,ItemSeqID,ItemSN,ItemID) VALUES('",B6,"',",C6,",",E6,",",G6,")"),"") -> INSERT INTO tbFinanceItemSeq(Report,ItemSeqID,ItemSN,ItemID) VALUES('PNLS',5,5,1085)
A7: Exist | B7: PNLS | C7: =D7 -> 6 | D7: 6 | E7: =F7 -> 6 | F7: 6 | G7: 1086 | H7: (PNL)Total Cost of Sales | I7: =IF(A7<>"Remove",CONCATENATE("INSERT INTO tbFinanceItemSeq(Report,ItemSeqID,ItemSN,ItemID) VALUES('",B7,"',",C7,",",E7,",",G7,")"),"") -> INSERT INTO tbFinanceItemSeq(Report,ItemSeqID,ItemSN,ItemID) VALUES('PNLS',6,6,1086)
A8: Exist | B8: PNLS | C8: =D8 -> 7 | D8: 7 | E8: =F8 -> 7 | F8: 7 | G8: 1087 | H8: (PNL)Gross Profit | I8: =IF(A8<>"Remove",CONCATENATE("INSERT INTO tbFinanceItemSeq(Report,ItemSeqID,ItemSN,ItemID) VALUES('",B8,"',",C8,",",E8,",",G8,")"),"") -> INSERT INTO tbFinanceItemSeq(Report,ItemSeqID,ItemSN,ItemID) VALUES('PNLS',7,7,1087)
A9: Exist | B9: PNLS | C9: =D9 -> 8 | D9: 8 | E9: =F9 -> 8 | F9: 8 | G9: 1088 | H9: (PNL)Commission Income/Mgt Income | I9: =IF(A9<>"Remove",CONCATENATE("INSERT INTO tbFinanceItemSeq(Report,ItemSeqID,ItemSN,ItemID) VALUES('",B9,"',",C9,",",E9,",",G9,")"),"") -> INSERT INTO tbFinanceItemSeq(Report,ItemSeqID,ItemSN,ItemID) VALUES('PNLS',8,8,1088)
A10: New | B10: PNLS | C10: 9 | E10: 9 | G10: 1126 | H10: (PNL)Gain/(Loss) Disposal of FA | I10: =IF(A10<>"Remove",CONCATENATE("INSERT INTO tbFinanceItemSeq(Report,ItemSeqID,ItemSN,ItemID) VALUES('",B10,"',",C10,",",E10,",",G10,")"),"") -> INSERT INTO tbFinanceItemSeq(Report,ItemSeqID,ItemSN,ItemID) VALUES('PNLS',9,9,1126)
A11: Exist | B11: PNLS | C11: =D11+1 -> 10 | D11: 9 | E11: =F11+1 -> 10 | F11: 9 | G11: 1089 | H11: (PNL)Other Op Income | I11: =IF(A11<>"Remove",CONCATENATE("INSERT INTO tbFinanceItemSeq(Report,ItemSeqID,ItemSN,ItemID) VALUES('",B11,"',",C11,",",E11,",",G11,")"),"") -> INSERT INTO tbFinanceItemSeq(Report,ItemSeqID,ItemSN,ItemID) VALUES('PNLS',10,10,1089)
A12: Exist | B12: PNLS | C12: =D12+1 -> 11 | D12: 10 | E12: =F12+1 -> 11 | F12: 10 | G12: 1090 | H12: (PNL)Other Op Expense | I12: =IF(A12<>"Remove",CONCATENATE("INSERT INTO tbFinanceItemSeq(Report,ItemSeqID,ItemSN,ItemID) VALUES('",B12,"',",C12,",",E12,",",G12,")"),"") -> INSERT INTO tbFinanceItemSeq(Report,ItemSeqID,ItemSN,ItemID) VALUES('PNLS',11,11,1090)
A13: Exist | B13: PNLS | C13: =D13+1 -> 12 | D13: 11 | E13: =F13+1 -> 12 | F13: 11 | G13: 1091 | H13: (PNL)Total Other Op Income/ (Exp) | I13: =IF(A13<>"Remove",CONCATENATE("INSERT INTO tbFinanceItemSeq(Report,ItemSeqID,ItemSN,ItemID) VALUES('",B13,"',",C13,",",E13,",",G13,")"),"") -> INSERT INTO tbFinanceItemSeq(Report,ItemSeqID,ItemSN,ItemID) VALUES('PNLS',12,12,1091)
A14: New | B14: PNLS | C14: 13 | E14: 13 | G14: =CONCATENATE("(SELECT TOP 1 ItemID FROM tbFinanceItem where ItemName = '",H14,"')") -> (SELECT TOP 1 ItemID FROM tbFinanceItem where ItemName = '(PNL)Selling & Distribution') | H14: (PNL)Selling & Distribution | I14: =IF(A14<>"Remove",CONCATENATE("INSERT INTO tbFinanceItemSeq(Report,ItemSeqID,ItemSN,ItemID) VALUES('",B14,"',",C14,",",E14,",",G14,")"),"") -> INSERT INTO tbFinanceItemSeq(Report,ItemSeqID,ItemSN,ItemID) VALUES('PNLS',13,13,(SELECT TOP 1 ItemID FROM tbFinanceItem where ItemName = '(PNL)Selling & Distribution'))
A15: Remove | B15: PNLS | C15: =D15+1 -> 13 | D15: 12 | E15: =F15+1 -> 13 | F15: 12 | G15: 1102 | H15: (PNL)Total S&D Expenses | I15: =IF(A15<>"Remove",CONCATENATE("INSERT INTO tbFinanceItemSeq(Report,ItemSeqID,ItemSN,ItemID) VALUES('",B15,"',",C15,",",E15,",",G15,")"),"")
A16: Exist | B16: PNLS | C16: =D16+1 -> 14 | D16: 13 | E16: =F16+1 -> 14 | F16: 13 | G16: 1112 | H16: (PNL)A&G Direct Expenses | I16: =IF(A16<>"Remove",CONCATENATE("INSERT INTO tbFinanceItemSeq(Report,ItemSeqID,ItemSN,ItemID) VALUES('",B16,"',",C16,",",E16,",",G16,")"),"") -> INSERT INTO tbFinanceItemSeq(Report,ItemSeqID,ItemSN,ItemID) VALUES('PNLS',14,14,1112)
A17: Exist | B17: PNLS | C17: =D17+1 -> 15 | D17: 14 | E17: =F17+1 -> 15 | F17: 14 | G17: 1118 | H17: (PNL)A&G Other Expenses | I17: =IF(A17<>"Remove",CONCATENATE("INSERT INTO tbFinanceItemSeq(Report,ItemSeqID,ItemSN,ItemID) VALUES('",B17,"',",C17,",",E17,",",G17,")"),"") -> INSERT INTO tbFinanceItemSeq(Report,ItemSeqID,ItemSN,ItemID) VALUES('PNLS',15,15,1118)
A18: Exist | B18: PNLS | C18: =D18+1 -> 16 | D18: 15 | E18: =F18+1 -> 16 | F18: 15 | G18: 1120 | H18: (PNL)Profit from Operations | I18: =IF(A18<>"Remove",CONCATENATE("INSERT INTO tbFinanceItemSeq(Report,ItemSeqID,ItemSN,ItemID) VALUES('",B18,"',",C18,",",E18,",",G18,")"),"") -> INSERT INTO tbFinanceItemSeq(Report,ItemSeqID,ItemSN,ItemID) VALUES('PNLS',16,16,1120)
A19: Exist | B19: PNLS | C19: =D19+1 -> 17 | D19: 16 | E19: =F19+1 -> 17 | F19: 16 | G19: 1121 | H19: (PNL)Interest Income | I19: =IF(A19<>"Remove",CONCATENATE("INSERT INTO tbFinanceItemSeq(Report,ItemSeqID,ItemSN,ItemID) VALUES('",B19,"',",C19,",",E19,",",G19,")"),"") -> INSERT INTO tbFinanceItemSeq(Report,ItemSeqID,ItemSN,ItemID) VALUES('PNLS',17,17,1121)
A20: Exist | B20: PNLS | C20: =D20+1 -> 18 | D20: 17 | E20: =F20+1 -> 18 | F20: 17 | G20: 1122 | H20: (PNL)Interest Expense | I20: =IF(A20<>"Remove",CONCATENATE("INSERT INTO tbFinanceItemSeq(Report,ItemSeqID,ItemSN,ItemID) VALUES('",B20,"',",C20,",",E20,",",G20,")"),"") -> INSERT INTO tbFinanceItemSeq(Report,ItemSeqID,ItemSN,ItemID) VALUES('PNLS',18,18,1122)
A21: New | B21: PNLS | C21: 19 | E21: 19 | G21: =CONCATENATE("(SELECT ItemID FROM tbFinanceItem where ItemName = '",H21,"')") -> (SELECT ItemID FROM tbFinanceItem where ItemName = '(PNL)Derivatives Gain/(Loss)') | H21: (PNL)Derivatives Gain/(Loss) | I21: =IF(A21<>"Remove",CONCATENATE("INSERT INTO tbFinanceItemSeq(Report,ItemSeqID,ItemSN,ItemID) VALUES('",B21,"',",C21,",",E21,",",G21,")"),"") -> INSERT INTO tbFinanceItemSeq(Report,ItemSeqID,ItemSN,ItemID) VALUES('PNLS',19,19,(SELECT ItemID FROM tbFinanceItem where ItemName = '(PNL)Derivatives Gain/(Loss)'))
A22: New | B22: PNLS | C22: 20 | E22: 20 | G22: =CONCATENATE("(SELECT ItemID FROM tbFinanceItem where ItemName = '",H22,"')") -> (SELECT ItemID FROM tbFinanceItem where ItemName = '(PNL)Forex Gain/(Loss)') | H22: (PNL)Forex Gain/(Loss) | I22: =IF(A22<>"Remove",CONCATENATE("INSERT INTO tbFinanceItemSeq(Report,ItemSeqID,ItemSN,ItemID) VALUES('",B22,"',",C22,",",E22,",",G22,")"),"") -> INSERT INTO tbFinanceItemSeq(Report,ItemSeqID,ItemSN,ItemID) VALUES('PNLS',20,20,(SELECT ItemID FROM tbFinanceItem where ItemName = '(PNL)Forex Gain/(Loss)'))
A23: Remove | B23: PNLS | C23: =D23+1 -> 19 | D23: 18 | E23: =F23+1 -> 19 | F23: 18 | G23: 1123 | H23: (PNL)Realised Forex Gain/(Loss) | I23: =IF(A23<>"Remove",CONCATENATE("INSERT INTO tbFinanceItemSeq(Report,ItemSeqID,ItemSN,ItemID) VALUES('",B23,"',",C23,",",E23,",",G23,")"),"")
A24: Remove | B24: PNLS | C24: =D24+1 -> 20 | D24: 19 | E24: =F24+1 -> 20 | F24: 19 | G24: 1124 | H24: (PNL)Unrealised Forex Gain/(Loss) | I24: =IF(A24<>"Remove",CONCATENATE("INSERT INTO tbFinanceItemSeq(Report,ItemSeqID,ItemSN,ItemID) VALUES('",B24,"',",C24,",",E24,",",G24,")"),"")
A25: Exist | B25: PNLS | C25: =D25+1 -> 21 | D25: 20 | E25: =F25+1 -> 21 | F25: 20 | G25: 1125 | H25: (PNL)Dividend Income | I25: =IF(A25<>"Remove",CONCATENATE("INSERT INTO tbFinanceItemSeq(Report,ItemSeqID,ItemSN,ItemID) VALUES('",B25,"',",C25,",",E25,",",G25,")"),"") -> INSERT INTO tbFinanceItemSeq(Report,ItemSeqID,ItemSN,ItemID) VALUES('PNLS',21,21,1125)
A26: Remove | B26: PNLS | C26: =D26+1 -> 22 | D26: 21 | E26: =F26+1 -> 22 | F26: 21 | G26: 1126 | H26: (PNL)Gain/(Loss) Disposal of FA | I26: =IF(A26<>"Remove",CONCATENATE("INSERT INTO tbFinanceItemSeq(Report,ItemSeqID,ItemSN,ItemID) VALUES('",B26,"',",C26,",",E26,",",G26,")"),"")
A27: Exist | B27: PNLS | C27: =D27 -> 22 | D27: 22 | E27: =F27 -> 22 | F27: 22 | G27: 1127 | H27: (PNL)Other Non-Op Income/(Exp) | I27: =IF(A27<>"Remove",CONCATENATE("INSERT INTO tbFinanceItemSeq(Report,ItemSeqID,ItemSN,ItemID) VALUES('",B27,"',",C27,",",E27,",",G27,")"),"") -> INSERT INTO tbFinanceItemSeq(Report,ItemSeqID,ItemSN,ItemID) VALUES('PNLS',22,22,1127)
A28: Exist | B28: PNLS | C28: =D28 -> 23 | D28: 23 | E28: =F28 -> 23 | F28: 23 | G28: 1128 | H28: (PNL)Total Non-Op Income/(Exp) | I28: =IF(A28<>"Remove",CONCATENATE("INSERT INTO tbFinanceItemSeq(Report,ItemSeqID,ItemSN,ItemID) VALUES('",B28,"',",C28,",",E28,",",G28,")"),"") -> INSERT INTO tbFinanceItemSeq(Report,ItemSeqID,ItemSN,ItemID) VALUES('PNLS',23,23,1128)
A29: Exist | B29: PNLS | C29: =D29 -> 24 | D29: 24 | E29: =F29 -> 24 | F29: 24 | G29: 1129 | H29: (PNL)Profit Before Taxation | I29: =IF(A29<>"Remove",CONCATENATE("INSERT INTO tbFinanceItemSeq(Report,ItemSeqID,ItemSN,ItemID) VALUES('",B29,"',",C29,",",E29,",",G29,")"),"") -> INSERT INTO tbFinanceItemSeq(Report,ItemSeqID,ItemSN,ItemID) VALUES('PNLS',24,24,1129)
A30: Exist | B30: PNLS | C30: =D30 -> 25 | D30: 25 | E30: =F30 -> 25 | F30: 25 | G30: 1130 | H30: (PNL)Less: Taxation | I30: =IF(A30<>"Remove",CONCATENATE("INSERT INTO tbFinanceItemSeq(Report,ItemSeqID,ItemSN,ItemID) VALUES('",B30,"',",C30,",",E30,",",G30,")"),"") -> INSERT INTO tbFinanceItemSeq(Report,ItemSeqID,ItemSN,ItemID) VALUES('PNLS',25,25,1130)
A31: Remove | B31: PNLS | C31: =D31 -> 26 | D31: 26 | E31: =F31 -> 26 | F31: 26 | G31: 1131 | H31: (PNL)Profit After Taxation | I31: =IF(A31<>"Remove",CONCATENATE("INSERT INTO tbFinanceItemSeq(Report,ItemSeqID,ItemSN,ItemID) VALUES('",B31,"',",C31,",",E31,",",G31,")"),"")
A32: New | B32: PNLS | C32: =D32 -> 26 | D32: 26 | E32: =F32 -> 26 | F32: 26 | G32: 1131 | H32: (PNL)Profits After Taxation | I32: =IF(A32<>"Remove",CONCATENATE("INSERT INTO tbFinanceItemSeq(Report,ItemSeqID,ItemSN,ItemID) VALUES('",B32,"',",C32,",",E32,",",G32,")"),"") -> INSERT INTO tbFinanceItemSeq(Report,ItemSeqID,ItemSN,ItemID) VALUES('PNLS',26,26,1131)
A33: Exist | B33: PNLS | C33: =D33 -> 27 | D33: 27 | E33: =F33 -> 27 | F33: 27 | G33: 1474 | H33: (PNL)Dividend Expenses | I33: =IF(A33<>"Remove",CONCATENATE("INSERT INTO tbFinanceItemSeq(Report,ItemSeqID,ItemSN,ItemID) VALUES('",B33,"',",C33,",",E33,",",G33,")"),"") -> INSERT INTO tbFinanceItemSeq(Report,ItemSeqID,ItemSN,ItemID) VALUES('PNLS',27,27,1474)
A34: Exist | B34: PNLS | C34: =D34 -> 28 | D34: 28 | E34: =F34 -> 0 | F34: 0 | G34: 46 | H34: Performance Indicators | I34: =IF(A34<>"Remove",CONCATENATE("INSERT INTO tbFinanceItemSeq(Report,ItemSeqID,ItemSN,ItemID) VALUES('",B34,"',",C34,",",E34,",",G34,")"),"") -> INSERT INTO tbFinanceItemSeq(Report,ItemSeqID,ItemSN,ItemID) VALUES('PNLS',28,0,46)
A35: Exist | B35: PNLS | C35: =D35 -> 29 | D35: 29 | E35: =F35 -> 1 | F35: 1 | G35: 1135 | H35: Gross Profits Margin % | I35: =IF(A35<>"Remove",CONCATENATE("INSERT INTO tbFinanceItemSeq(Report,ItemSeqID,ItemSN,ItemID) VALUES('",B35,"',",C35,",",E35,",",G35,")"),"") -> INSERT INTO tbFinanceItemSeq(Report,ItemSeqID,ItemSN,ItemID) VALUES('PNLS',29,1,1135)
A36: Exist | B36: PNLS | C36: =D36 -> 30 | D36: 30 | E36: =F36 -> 2 | F36: 2 | G36: 1136 | H36: - External Sales GP % | I36: =IF(A36<>"Remove",CONCATENATE("INSERT INTO tbFinanceItemSeq(Report,ItemSeqID,ItemSN,ItemID) VALUES('",B36,"',",C36,",",E36,",",G36,")"),"") -> INSERT INTO tbFinanceItemSeq(Report,ItemSeqID,ItemSN,ItemID) VALUES('PNLS',30,2,1136)
A37: Exist | B37: PNLS | C37: =D37 -> 31 | D37: 31 | E37: =F37 -> 3 | F37: 3 | G37: 1137 | H37: - Interco Sales GP % | I37: =IF(A37<>"Remove",CONCATENATE("INSERT INTO tbFinanceItemSeq(Report,ItemSeqID,ItemSN,ItemID) VALUES('",B37,"',",C37,",",E37,",",G37,")"),"") -> INSERT INTO tbFinanceItemSeq(Report,ItemSeqID,ItemSN,ItemID) VALUES('PNLS',31,3,1137)
A38: Exist | B38: PNLS | C38: =D38 -> 32 | D38: 32 | E38: =F38 -> 4 | F38: 4 | G38: 50 | H38: Selling & Dist Margin % | I38: =IF(A38<>"Remove",CONCATENATE("INSERT INTO tbFinanceItemSeq(Report,ItemSeqID,ItemSN,ItemID) VALUES('",B38,"',",C38,",",E38,",",G38,")"),"") -> INSERT INTO tbFinanceItemSeq(Report,ItemSeqID,ItemSN,ItemID) VALUES('PNLS',32,4,50)
A39: Remove | B39: PNLS | C39: =D39 -> 33 | D39: 33 | E39: =F39 -> 5 | F39: 5 | G39: 1138 | H39: A&G Margin Direct % | I39: =IF(A39<>"Remove",CONCATENATE("INSERT INTO tbFinanceItemSeq(Report,ItemSeqID,ItemSN,ItemID) VALUES('",B39,"',",C39,",",E39,",",G39,")"),"")
A40: Exist | B40: PNLS | C40: 33 | D40: 34 | E40: 5 | F40: 6 | G40: 1139 | H40: A&G Margin Total % | I40: =IF(A40<>"Remove",CONCATENATE("INSERT INTO tbFinanceItemSeq(Report,ItemSeqID,ItemSN,ItemID) VALUES('",B40,"',",C40,",",E40,",",G40,")"),"") -> INSERT INTO tbFinanceItemSeq(Report,ItemSeqID,ItemSN,ItemID) VALUES('PNLS',33,5,1139)
...

Sheet F121 F24 Debug
A1: SELECT TOP 10 * FROM tbReport where ReportID = 433;
A2: --F121 Manufacturing Account.rpt
A3: --procReportFinanceMA
A4: --(BS)
A6: select s.* , i.ItemName from tbFinanceItemSeq s
A7: LEFT JOIN tbFinanceItem i on s.ItemID = i.ItemID
A8: where s.Report = 'MA'
A9: order by s.ItemSeqID
A12: DELETE FROM tbFinanceItemSeq where Report = 'MA'
A14: Update tbReport
A15: set FileName = 'F121 Manufacturing Account.rpt' ,
A16: Description = '[COA2016] F24 Manufacturing Account'
A17: where ReportID =433;

Sheet F121 F24 Origin
A1: Report | B1: ItemSeqID | C1: ItemSN | D1: ItemID | E1: ItemName
A2: MA | B2: 1 | C2: 1 | D2: 1280 | E2: (MA)Planned Production (M3 / KG)
A3: MA | B3: 2 | C3: 2 | D3: 1281 | E3: (MA)Actual Production (M3 / KG)
A4: MA | B4: 3 | C4: 3 | D4: 1282 | E4: (MA)Variance (M3 / KG)
A5: MA | B5: 4 | C5: 4 | D5: 1283 | E5: (MA)Manufacturing Costs
A6: MA | B6: 5 | C6: 5 | D6: 1284 | E6: (MA)DM-Raw Materials
A7: MA | B7: 6 | C7: 6 | D7: 1285 | E7: (MA)DM-Parts & Access
A8: MA | B8: 7 | C8: 7 | D8: 1286 | E8: (MA)DM-Packing & Label Materials
A9: MA | B9: 8 | C9: 8 | D9: 1287 | E9: (MA)DM-Others
A10: MA | B10: 9 | C10: 9 | D10: 1288 | E10: (MA)Direct Material
A11: MA | B11: 10 | C11: 10 | D11: 1289 | E11: (MA)DL-Salary & Leave
A12: MA | B12: 11 | C12: 11 | D12: 1290 | E12: (MA)DL-Bonus
A13: MA | B13: 12 | C13: 12 | D13: 1291 | E13: (MA)DL-Foreign Workers/Casual/Temp
... A65: MA | B65: 64 | C65: 9 | D65: 1342 | E65: (MA)Manufacturing Costs (m3/ Kg)

Sheet F121 F24 Dif
A1: Old | B1: New | C1: Diff | D1: Is Exist Name | E1: Is Exist | F1: Is New | G1: Is Remove | H1: Remark
A2: Planned Production (M3 / KG) | C2: =EXACT(A2,B2) -> FALSE | D2: =VLOOKUP(B2, A2:A336, 1, FALSE) -> #N/A | E2: =IF((AND(EXACT(C2,"TRUE"),_xlfn.IFNA(D2,"NA")<>"NA")),"Exist","") | F2: =IF((AND(EXACT(C2,"FALSE"),_xlfn.IFNA(D2,"NA")="NA")),"New","") -> New | G2: =IF((AND(ISBLANK(B2),EXACT(C2,"FALSE"))),"Remove","") -> Remove
A3: Actual Production (M3 / KG) | C3: =EXACT(A3,B3) -> FALSE | D3: =VLOOKUP(B3, A3:A337, 1, FALSE) -> #N/A | E3: =IF((AND(EXACT(C3,"TRUE"),_xlfn.IFNA(D3,"NA")<>"NA")),"Exist","") | F3: =IF((AND(EXACT(C3,"FALSE"),_xlfn.IFNA(D3,"NA")="NA")),"New","") -> New | G3: =IF((AND(ISBLANK(B3),EXACT(C3,"FALSE"))),"Remove","") -> Remove
A4: Variance (M3 / KG) | C4: =EXACT(A4,B4) -> FALSE | D4: =VLOOKUP(B4, A4:A338, 1, FALSE) -> #N/A | E4: =IF((AND(EXACT(C4,"TRUE"),_xlfn.IFNA(D4,"NA")<>"NA")),"Exist","") | F4: =IF((AND(EXACT(C4,"FALSE"),_xlfn.IFNA(D4,"NA")="NA")),"New","") -> New | G4: =IF((AND(ISBLANK(B4),EXACT(C4,"FALSE"))),"Remove","") -> Remove
A5: Manufacturing Costs | B5: Manufacturing Costs | C5: =EXACT(A5,B5) -> TRUE | D5: =VLOOKUP(B5, A5:A339, 1, FALSE) -> Manufacturing Costs | E5: =IF((AND(EXACT(C5,"TRUE"),_xlfn.IFNA(D5,"NA")<>"NA")),"Exist","") -> Exist | F5: =IF((AND(EXACT(C5,"FALSE"),_xlfn.IFNA(D5,"NA")="NA")),"New","") | G5: =IF((AND(ISBLANK(B5),EXACT(C5,"FALSE"))),"Remove","")
A6: DM-Raw Materials | B6: DM-Raw Materials | C6: =EXACT(A6,B6) -> TRUE | D6: =VLOOKUP(B6, A6:A340, 1, FALSE) -> DM-Raw Materials | E6: =IF((AND(EXACT(C6,"TRUE"),_xlfn.IFNA(D6,"NA")<>"NA")),"Exist","") -> Exist | F6: =IF((AND(EXACT(C6,"FALSE"),_xlfn.IFNA(D6,"NA")="NA")),"New","") | G6: =IF((AND(ISBLANK(B6),EXACT(C6,"FALSE"))),"Remove","")
A7: DM-Parts & Access | B7: DM-Parts & Access | C7: =EXACT(A7,B7) -> TRUE | D7: =VLOOKUP(B7, A7:A341, 1, FALSE) -> DM-Parts & Access | E7: =IF((AND(EXACT(C7,"TRUE"),_xlfn.IFNA(D7,"NA")<>"NA")),"Exist","") -> Exist | F7: =IF((AND(EXACT(C7,"FALSE"),_xlfn.IFNA(D7,"NA")="NA")),"New","") | G7: =IF((AND(ISBLANK(B7),EXACT(C7,"FALSE"))),"Remove","")
A8: DM-Packing & Label Materials | B8: DM-Packing & Label Materials | C8: =EXACT(A8,B8) -> TRUE | D8: =VLOOKUP(B8, A8:A342, 1, FALSE) -> DM-Packing & Label Materials | E8: =IF((AND(EXACT(C8,"TRUE"),_xlfn.IFNA(D8,"NA")<>"NA")),"Exist","") -> Exist | F8: =IF((AND(EXACT(C8,"FALSE"),_xlfn.IFNA(D8,"NA")="NA")),"New","") | G8: =IF((AND(ISBLANK(B8),EXACT(C8,"FALSE"))),"Remove","")
A9: DM-Others | B9: DM-Others | C9: =EXACT(A9,B9) -> TRUE | D9: =VLOOKUP(B9, A9:A343, 1, FALSE) -> DM-Others | E9: =IF((AND(EXACT(C9,"TRUE"),_xlfn.IFNA(D9,"NA")<>"NA")),"Exist","") -> Exist | F9: =IF((AND(EXACT(C9,"FALSE"),_xlfn.IFNA(D9,"NA")="NA")),"New","") | G9: =IF((AND(ISBLANK(B9),EXACT(C9,"FALSE"))),"Remove","")
A10: Direct Material | B10: Direct Material | C10: =EXACT(A10,B10) -> TRUE | D10: =VLOOKUP(B10, A10:A344, 1, FALSE) -> Direct Material | E10: =IF((AND(EXACT(C10,"TRUE"),_xlfn.IFNA(D10,"NA")<>"NA")),"Exist","") -> Exist | F10: =IF((AND(EXACT(C10,"FALSE"),_xlfn.IFNA(D10,"NA")="NA")),"New","") | G10: =IF((AND(ISBLANK(B10),EXACT(C10,"FALSE"))),"Remove","")
A11: Salary & Leave | B11: Salary & Leave | C11: =EXACT(A11,B11) -> TRUE | D11: =VLOOKUP(B11, A11:A345, 1, FALSE) -> Salary & Leave | E11: =IF((AND(EXACT(C11,"TRUE"),_xlfn.IFNA(D11,"NA")<>"NA")),"Exist","") -> Exist | F11: =IF((AND(EXACT(C11,"FALSE"),_xlfn.IFNA(D11,"NA")="NA")),"New","") | G11: =IF((AND(ISBLANK(B11),EXACT(C11,"FALSE"))),"Remove","")
A12: Bonus | B12: Bonus | C12: =EXACT(A12,B12) -> TRUE | D12: =VLOOKUP(B12, A12:A346, 1, FALSE) -> Bonus | E12: =IF((AND(EXACT(C12,"TRUE"),_xlfn.IFNA(D12,"NA")<>"NA")),"Exist","") -> Exist | F12: =IF((AND(EXACT(C12,"FALSE"),_xlfn.IFNA(D12,"NA")="NA")),"New","") | G12: =IF((AND(ISBLANK(B12),EXACT(C12,"FALSE"))),"Remove","")
A13: Foreign Workers/Casual/Temp | B13: Foreign Workers/Casual/Temp | C13: =EXACT(A13,B13) -> TRUE | D13: =VLOOKUP(B13, A13:A347, 1, FALSE) -> Foreign Workers/Casual/Temp | E13: =IF((AND(EXACT(C13,"TRUE"),_xlfn.IFNA(D13,"NA")<>"NA")),"Exist","") -> Exist | F13: =IF((AND(EXACT(C13,"FALSE"),_xlfn.IFNA(D13,"NA")="NA")),"New","") | G13: =IF((AND(ISBLANK(B13),EXACT(C13,"FALSE"))),"Remove","")
A14: Contractors | C14: =EXACT(A14,B14) -> FALSE | D14: =VLOOKUP(B14, A14:A348, 1, FALSE) -> #N/A | E14: =IF((AND(EXACT(C14,"TRUE"),_xlfn.IFNA(D14,"NA")<>"NA")),"Exist","") | F14: =IF((AND(EXACT(C14,"FALSE"),_xlfn.IFNA(D14,"NA")="NA")),"New","") -> New | G14: =IF((AND(ISBLANK(B14),EXACT(C14,"FALSE"))),"Remove","") -> Remove
A15: DL-Overtime | B15: DL-Overtime | C15: =EXACT(A15,B15) -> TRUE | D15: =VLOOKUP(B15, A15:A349, 1, FALSE) -> DL-Overtime | E15: =IF((AND(EXACT(C15,"TRUE"),_xlfn.IFNA(D15,"NA")<>"NA")),"Exist","") -> Exist | F15: =IF((AND(EXACT(C15,"FALSE"),_xlfn.IFNA(D15,"NA")="NA")),"New","") | G15: =IF((AND(ISBLANK(B15),EXACT(C15,"FALSE"))),"Remove","")
A16: DL-Shift Allowance & Incentive | B16: DL-Shift Allowance & Incentive | C16: =EXACT(A16,B16) -> TRUE | D16: =VLOOKUP(B16, A16:A350, 1, FALSE) -> DL-Shift Allowance & Incentive | E16: =IF((AND(EXACT(C16,"TRUE"),_xlfn.IFNA(D16,"NA")<>"NA")),"Exist","") -> Exist | F16: =IF((AND(EXACT(C16,"FALSE"),_xlfn.IFNA(D16,"NA")="NA")),"New","") | G16: =IF((AND(ISBLANK(B16),EXACT(C16,"FALSE"))),"Remove","")
A17: DL-Staff Transport/Vehicle Rental | B17: DL-Staff Transport/Vehicle Rental | C17: =EXACT(A17,B17) -> TRUE | D17: =VLOOKUP(B17, A17:A351, 1, FALSE) -> DL-Staff Transport/Vehicle Rental | E17: =IF((AND(EXACT(C17,"TRUE"),_xlfn.IFNA(D17,"NA")<>"NA")),"Exist","") -> Exist | F17: =IF((AND(EXACT(C17,"FALSE"),_xlfn.IFNA(D17,"NA")="NA")),"New","") | G17: =IF((AND(ISBLANK(B17),EXACT(C17,"FALSE"))),"Remove","")
A18: DL-Social Security Contribution | B18: DL-Social Security Contribution | C18: =EXACT(A18,B18) -> TRUE | D18: =VLOOKUP(B18, A18:A352, 1, FALSE) -> DL-Social Security Contribution | E18: =IF((AND(EXACT(C18,"TRUE"),_xlfn.IFNA(D18,"NA")<>"NA")),"Exist","") -> Exist | F18: =IF((AND(EXACT(C18,"FALSE"),_xlfn.IFNA(D18,"NA")="NA")),"New","") | G18: =IF((AND(ISBLANK(B18),EXACT(C18,"FALSE"))),"Remove","")
A19: DL-Workers` Levy | B19: DL-Workers` Levy | C19: =EXACT(A19,B19) -> TRUE | D19: =VLOOKUP(B19, A19:A353, 1, FALSE) -> DL-Workers` Levy | E19: =IF((AND(EXACT(C19,"TRUE"),_xlfn.IFNA(D19,"NA")<>"NA")),"Exist","") -> Exist | F19: =IF((AND(EXACT(C19,"FALSE"),_xlfn.IFNA(D19,"NA")="NA")),"New","") | G19: =IF((AND(ISBLANK(B19),EXACT(C19,"FALSE"))),"Remove","")
A20: DL-Others Direct Labor Costs | B20: DL-Others Direct Labor Costs | C20: =EXACT(A20,B20) -> TRUE | D20: =VLOOKUP(B20, A20:A354, 1, FALSE) -> DL-Others Direct Labor Costs | E20: =IF((AND(EXACT(C20,"TRUE"),_xlfn.IFNA(D20,"NA")<>"NA")),"Exist","") -> Exist | F20: =IF((AND(EXACT(C20,"FALSE"),_xlfn.IFNA(D20,"NA")="NA")),"New","") | G20: =IF((AND(ISBLANK(B20),EXACT(C20,"FALSE"))),"Remove","")
A21: Direct Labor | B21: Direct Labor | C21: =EXACT(A21,B21) -> TRUE | D21: =VLOOKUP(B21, A21:A355, 1, FALSE) -> Direct Labor | E21: =IF((AND(EXACT(C21,"TRUE"),_xlfn.IFNA(D21,"NA")<>"NA")),"Exist","") -> Exist | F21: =IF((AND(EXACT(C21,"FALSE"),_xlfn.IFNA(D21,"NA")="NA")),"New","") | G21: =IF((AND(ISBLANK(B21),EXACT(C21,"FALSE"))),"Remove","")
A22: Direct Expenses | B22: Direct Expenses | C22: =EXACT(A22,B22) -> TRUE | D22: =VLOOKUP(B22, A22:A356, 1, FALSE) -> Direct Expenses | E22: =IF((AND(EXACT(C22,"TRUE"),_xlfn.IFNA(D22,"NA")<>"NA")),"Exist","") -> Exist | F22: =IF((AND(EXACT(C22,"FALSE"),_xlfn.IFNA(D22,"NA")="NA")),"New","") | G22: =IF((AND(ISBLANK(B22),EXACT(C22,"FALSE"))),"Remove","")
A23: Prime Cost | B23: Prime Cost | C23: =EXACT(A23,B23) -> TRUE | D23: =VLOOKUP(B23, A23:A357, 1, FALSE) -> Prime Cost | E23: =IF((AND(EXACT(C23,"TRUE"),_xlfn.IFNA(D23,"NA")<>"NA")),"Exist","") -> Exist | F23: =IF((AND(EXACT(C23,"FALSE"),_xlfn.IFNA(D23,"NA")="NA")),"New","") | G23: =IF((AND(ISBLANK(B23),EXACT(C23,"FALSE"))),"Remove","")
A24: Indirect Material | B24: Indirect Material | C24: =EXACT(A24,B24) -> TRUE | D24: =VLOOKUP(B24, A24:A358, 1, FALSE) -> Indirect Material | E24: =IF((AND(EXACT(C24,"TRUE"),_xlfn.IFNA(D24,"NA")<>"NA")),"Exist","") -> Exist | F24: =IF((AND(EXACT(C24,"FALSE"),_xlfn.IFNA(D24,"NA")="NA")),"New","") | G24: =IF((AND(ISBLANK(B24),EXACT(C24,"FALSE"))),"Remove","")
A25: IL-Salary & Leave | B25: IL-Salary & Leave | C25: =EXACT(A25,B25) -> TRUE | D25: =VLOOKUP(B25, A25:A359, 1, FALSE) -> IL-Salary & Leave | E25: =IF((AND(EXACT(C25,"TRUE"),_xlfn.IFNA(D25,"NA")<>"NA")),"Exist","") -> Exist | F25: =IF((AND(EXACT(C25,"FALSE"),_xlfn.IFNA(D25,"NA")="NA")),"New","") | G25: =IF((AND(ISBLANK(B25),EXACT(C25,"FALSE"))),"Remove","")
A26: IL-Bonus | B26: IL-Bonus | C26: =EXACT(A26,B26) -> TRUE | D26: =VLOOKUP(B26, A26:A360, 1, FALSE) -> IL-Bonus | E26: =IF((AND(EXACT(C26,"TRUE"),_xlfn.IFNA(D26,"NA")<>"NA")),"Exist","") -> Exist | F26: =IF((AND(EXACT(C26,"FALSE"),_xlfn.IFNA(D26,"NA")="NA")),"New","") | G26: =IF((AND(ISBLANK(B26),EXACT(C26,"FALSE"))),"Remove","")
... A34: IL-Other Indirect Labor Costs | B34: IL-Other Indirect Labor Costs | C34: =EXACT(A34,B34) -> TRUE | D34: =VLOOKUP(B34, A34:A368, 1, FALSE) -> IL-Other Indirect Labor Costs | E34: =IF((AND(EXACT(C34,"TRUE"),_xlfn.IFNA(D34,"NA")<>"NA")),"Exist","") -> Exist | F34: =IF((AND(EXACT(C34,"FALSE"),_xlfn.IFNA(D34,"NA")="NA")),"New","") | G34: =IF((AND(ISBLANK(B34),EXACT(C34,"FALSE"))),"Remove","")
B35: QA Allocated Cost | C35: =EXACT(A35,B35) -> FALSE | D35: =VLOOKUP(B35, A35:A369, 1, FALSE) -> #N/A | E35: =IF((AND(EXACT(C35,"TRUE"),_xlfn.IFNA(D35,"NA")<>"NA")),"Exist","") | F35: =IF((AND(EXACT(C35,"FALSE"),_xlfn.IFNA(D35,"NA")="NA")),"New","") -> New | G35: =IF((AND(ISBLANK(B35),EXACT(C35,"FALSE"))),"Remove","")
B36: PM Allocated Cost | C36: =EXACT(A36,B36) -> FALSE | D36: =VLOOKUP(B36, A36:A370, 1, FALSE) -> #N/A | E36: =IF((AND(EXACT(C36,"TRUE"),_xlfn.IFNA(D36,"NA")<>"NA")),"Exist","") | F36: =IF((AND(EXACT(C36,"FALSE"),_xlfn.IFNA(D36,"NA")="NA")),"New","") -> New | G36: =IF((AND(ISBLANK(B36),EXACT(C36,"FALSE"))),"Remove","")
A37: Indirect Labor | B37: Indirect Labor | C37: =EXACT(A37,B37) -> TRUE | D37: =VLOOKUP(B37, A37:A371, 1, FALSE) -> Indirect Labor | E37: =IF((AND(EXACT(C37,"TRUE"),_xlfn.IFNA(D37,"NA")<>"NA")),"Exist","") -> Exist | F37: =IF((AND(EXACT(C37,"FALSE"),_xlfn.IFNA(D37,"NA")="NA")),"New","") | G37: =IF((AND(ISBLANK(B37),EXACT(C37,"FALSE"))),"Remove","")
A38: Utilities - Elec, Water, Gas | B38: Utilities - Elec, Water, Gas | C38: =EXACT(A38,B38) -> TRUE | D38: =VLOOKUP(B38, A38:A372, 1, FALSE) -> Utilities - Elec, Water, Gas | E38: =IF((AND(EXACT(C38,"TRUE"),_xlfn.IFNA(D38,"NA")<>"NA")),"Exist","") -> Exist | F38: =IF((AND(EXACT(C38,"FALSE"),_xlfn.IFNA(D38,"NA")="NA")),"New","") | G38: =IF((AND(ISBLANK(B38),EXACT(C38,"FALSE"))),"Remove","")
A39: Product Development/Testing | B39: Product Development/Testing | C39: =EXACT(A39,B39) -> TRUE | D39: =VLOOKUP(B39, A39:A373, 1, FALSE) -> Product Development/Testing | E39: =IF((AND(EXACT(C39,"TRUE"),_xlfn.IFNA(D39,"NA")<>"NA")),"Exist","") -> Exist | F39: =IF((AND(EXACT(C39,"FALSE"),_xlfn.IFNA(D39,"NA")="NA")),"New","") | G39: =IF((AND(ISBLANK(B39),EXACT(C39,"FALSE"))),"Remove","")
A40: Carriage/Transport | C40: =EXACT(A40,B40) -> FALSE | D40: =VLOOKUP(B40, A40:A374, 1, FALSE) -> #N/A | E40: =IF((AND(EXACT(C40,"TRUE"),_xlfn.IFNA(D40,"NA")<>"NA")),"Exist","") | F40: =IF((AND(EXACT(C40,"FALSE"),_xlfn.IFNA(D40,"NA")="NA")),"New","") -> New | G40: =IF((AND(ISBLANK(B40),EXACT(C40,"FALSE"))),"Remove","") -> Remove
B41: Carriage/Transport/Storage | C41: =EXACT(A41,B41) -> FALSE | D41: =VLOOKUP(B41, A41:A375, 1, FALSE) -> #N/A | E41: =IF((AND(EXACT(C41,"TRUE"),_xlfn.IFNA(D41,"NA")<>"NA")),"Exist","") | F41: =IF((AND(EXACT(C41,"FALSE"),_xlfn.IFNA(D41,"NA")="NA")),"New","") -> New | G41: =IF((AND(ISBLANK(B41),EXACT(C41,"FALSE"))),"Remove","")
A42: Manufacturing Loss/Wastage | B42: Manufacturing Loss/Wastage | C42: =EXACT(A42,B42) -> TRUE | D42: =VLOOKUP(B42, A42:A376, 1, FALSE) -> Manufacturing Loss/Wastage | E42: =IF((AND(EXACT(C42,"TRUE"),_xlfn.IFNA(D42,"NA")<>"NA")),"Exist","") -> Exist | F42: =IF((AND(EXACT(C42,"FALSE"),_xlfn.IFNA(D42,"NA")="NA")),"New","") | G42: =IF((AND(ISBLANK(B42),EXACT(C42,"FALSE"))),"Remove","")
